Workbook
Name Vtas: Ventas_Wellpro[#All]
Name Vtas: Ventas_Wellpro4[#All]
Name Vtas: Ventas_Wellpro[#All]

Sheet Venta (2)
A1: Indica | B1: Fecha | C1: Producto | D1: Cliente | E1: Precio de Venta | F1: Cantidad Vendida | G1: IVA | H1: Total de Venta sin IVA | I1: Total de Venta con IVA | J1: Año | K1: Mes | L1: Día
B2: 45321 | C2: Inodoro Portatil con tapa y brazo | D2: Amazon | E2: 1068.94 | F2: 1 | G2: 171.03 | H2: 1068.94 | I2: 1239.97 | J2: =YEAR(Ventas_Wellpro4[[#This Row],[Fecha]]) -> 2024 | K2: =TEXT(Ventas_Wellpro4[[#This Row],[Fecha]],"MMMM") -> enero | L2: =DAY(Ventas_Wellpro4[[#This Row],[Fecha]]) -> 30
B3: 45321 | C3: Inodoro Portatil con tapa y brazo | D3: Amazon | E3: 1068.94 | F3: 3 | G3: 513.09 | H3: 3206.82 | I3: 3719.91 | J3: =YEAR(Ventas_Wellpro4[[#This Row],[Fecha]]) -> 2024 | K3: =TEXT(Ventas_Wellpro4[[#This Row],[Fecha]],"MMMM") -> enero | L3: =DAY(Ventas_Wellpro4[[#This Row],[Fecha]]) -> 30
B4: 45321 | C4: Silla de Baño con Respaldo | D4: Amazon | E4: 748.26 | F4: 1 | G4: 119.72 | H4: 748.26 | I4: 867.98 | J4: =YEAR(Ventas_Wellpro4[[#This Row],[Fecha]]) -> 2024 | K4: =TEXT(Ventas_Wellpro4[[#This Row],[Fecha]],"MMMM") -> enero | L4: =DAY(Ventas_Wellpro4[[#This Row],[Fecha]]) -> 30
B5: 45321 | C5: Silla de Baño con Respaldo | D5: Amazon | E5: 748.26 | F5: 3 | G5: 359.16 | H5: 2244.78 | I5: 2603.94 | J5: =YEAR(Ventas_Wellpro4[[#This Row],[Fecha]]) -> 2024 | K5: =TEXT(Ventas_Wellpro4[[#This Row],[Fecha]],"MMMM") -> enero | L5: =DAY(Ventas_Wellpro4[[#This Row],[Fecha]]) -> 30
B6: 45321 | C6: Silla de Ruedas STD | D6: Amazon | E6: 2419.7 | F6: 3 | G6: 1161.46 | H6: 7259.1 | I6: 8420.56 | J6: =YEAR(Ventas_Wellpro4[[#This Row],[Fecha]]) -> 2024 | K6: =TEXT(Ventas_Wellpro4[[#This Row],[Fecha]],"MMMM") -> enero | L6: =DAY(Ventas_Wellpro4[[#This Row],[Fecha]]) -> 30
B7: 45630 | C7: Nebulizador Adulto Compacto | D7: Farmacia San Pablo | E7: 505.86 | F7: 340 | G7: 27518.78 | H7: 171992.4 | I7: 199511.18 | J7: =YEAR(Ventas_Wellpro4[[#This Row],[Fecha]]) -> 2024 | K7: =TEXT(Ventas_Wellpro4[[#This Row],[Fecha]],"MMMM") -> diciembre | L7: =DAY(Ventas_Wellpro4[[#This Row],[Fecha]]) -> 4
B8: 45329 | C8: Báscula Digital de Vidrio Marmol | D8: Amazon | E8: 176.38 | F8: 6 | G8: 169.32 | H8: 1058.28 | I8: 1227.6 | J8: =YEAR(Ventas_Wellpro4[[#This Row],[Fecha]]) -> 2024 | K8: =TEXT(Ventas_Wellpro4[[#This Row],[Fecha]],"MMMM") -> febrero | L8: =DAY(Ventas_Wellpro4[[#This Row],[Fecha]]) -> 7
B9: 45329 | C9: Cojin Cuadrad Memory Foam | D9: Amazon | E9: 160.34 | F9: 5 | G9: 128.27 | H9: 801.7 | I9: 929.97 | J9: =YEAR(Ventas_Wellpro4[[#This Row],[Fecha]]) -> 2024 | K9: =TEXT(Ventas_Wellpro4[[#This Row],[Fecha]],"MMMM") -> febrero | L9: =DAY(Ventas_Wellpro4[[#This Row],[Fecha]]) -> 7
B10: 45329 | C10: Inodoro Portatil con tapa y brazo | D10: Amazon | E10: 1068.94 | F10: 1 | G10: 171.03 | H10: 1068.94 | I10: 1239.97 | J10: =YEAR(Ventas_Wellpro4[[#This Row],[Fecha]]) -> 2024 | K10: =TEXT(Ventas_Wellpro4[[#This Row],[Fecha]],"MMMM") -> febrero | L10: =DAY(Ventas_Wellpro4[[#This Row],[Fecha]]) -> 7
B11: 45329 | C11: Silla de Baño con Respaldo | D11: Amazon | E11: 748.26 | F11: 1 | G11: 119.72 | H11: 748.26 | I11: 867.98 | J11: =YEAR(Ventas_Wellpro4[[#This Row],[Fecha]]) -> 2024 | K11: =TEXT(Ventas_Wellpro4[[#This Row],[Fecha]],"MMMM") -> febrero | L11: =DAY(Ventas_Wellpro4[[#This Row],[Fecha]]) -> 7
B12: 45329 | C12: Silla de Ruedas STD | D12: Amazon | E12: 2419.7 | F12: 1 | G12: 387.15 | H12: 2419.7 | I12: 2806.85 | J12: =YEAR(Ventas_Wellpro4[[#This Row],[Fecha]]) -> 2024 | K12: =TEXT(Ventas_Wellpro4[[#This Row],[Fecha]],"MMMM") -> febrero | L12: =DAY(Ventas_Wellpro4[[#This Row],[Fecha]]) -> 7
B13: 45335 | C13: Báscula Digital de Vidrio Antideslizante | D13: Amazon | E13: 176.38 | F13: 6 | G13: 169.32 | H13: 1058.28 | I13: 1227.6 | J13: =YEAR(Ventas_Wellpro4[[#This Row],[Fecha]]) -> 2024 | K13: =TEXT(Ventas_Wellpro4[[#This Row],[Fecha]],"MMMM") -> febrero | L13: =DAY(Ventas_Wellpro4[[#This Row],[Fecha]]) -> 13
... B57: 45929 | C57: Nebulizador Adulto Compacto | D57: Farmacia Sana Sana | E57: 633.62 | F57: 4 | G57: 405.5168 | H57: 2534.48 | I57: 2939.9968 | J57: =YEAR(Ventas_Wellpro4[[#This Row],[Fecha]]) -> 2025 | K57: =TEXT(Ventas_Wellpro4[[#This Row],[Fecha]],"MMMM") -> septiembre | L57: =DAY(Ventas_Wellpro4[[#This Row],[Fecha]]) -> 29
B58: 45931 | C58: Nebulizador Adulto Walmart | D58: Walmart | E58: 498.66 | F58: 6 | G58: =+(Ventas_Wellpro4[[#This Row],[Precio de Venta]]*0.16)*Ventas_Wellpro4[[#This Row],[Cantidad Vendida]] -> 478.7136 | H58: 2991.96 | I58: =+Ventas_Wellpro4[[#This Row],[Total de Venta sin IVA]]+Ventas_Wellpro4[[#This Row],[IVA]] -> 3470.6736 | J58: =YEAR(Ventas_Wellpro4[[#This Row],[Fecha]]) -> 2025 | K58: =TEXT(Ventas_Wellpro4[[#This Row],[Fecha]],"MMMM") -> octubre | L58: =DAY(Ventas_Wellpro4[[#This Row],[Fecha]]) -> 1
B59: 45931 | C59: Nebulizador Adulto Walmart | D59: Walmart | E59: 498.66 | F59: 36 | G59: =+(Ventas_Wellpro4[[#This Row],[Precio de Venta]]*0.16)*Ventas_Wellpro4[[#This Row],[Cantidad Vendida]] -> 2872.2816 | H59: 17951.76 | I59: =+Ventas_Wellpro4[[#This Row],[Total de Venta sin IVA]]+Ventas_Wellpro4[[#This Row],[IVA]] -> 20824.042 | J59: =YEAR(Ventas_Wellpro4[[#This Row],[Fecha]]) -> 2025 | K59: =TEXT(Ventas_Wellpro4[[#This Row],[Fecha]],"MMMM") -> octubre | L59: =DAY(Ventas_Wellpro4[[#This Row],[Fecha]]) -> 1
B60: 45931 | C60: Nebulizador Adulto Walmart | D60: Walmart | E60: 498.66 | F60: 12 | G60: =+(Ventas_Wellpro4[[#This Row],[Precio de Venta]]*0.16)*Ventas_Wellpro4[[#This Row],[Cantidad Vendida]] -> 957.4272 | H60: 5983.92 | I60: =+Ventas_Wellpro4[[#This Row],[Total de Venta sin IVA]]+Ventas_Wellpro4[[#This Row],[IVA]] -> 6941.3472 | J60: =YEAR(Ventas_Wellpro4[[#This Row],[Fecha]]) -> 2025 | K60: =TEXT(Ventas_Wellpro4[[#This Row],[Fecha]],"MMMM") -> octubre | L60: =DAY(Ventas_Wellpro4[[#This Row],[Fecha]]) -> 1
B61: 45931 | C61: Nebulizador Adulto Walmart | D61: Walmart | E61: 498.66 | F61: 6 | G61: =+(Ventas_Wellpro4[[#This Row],[Precio de Venta]]*0.16)*Ventas_Wellpro4[[#This Row],[Cantidad Vendida]] -> 478.7136 | H61: 2991.96 | I61: =+Ventas_Wellpro4[[#This Row],[Total de Venta sin IVA]]+Ventas_Wellpro4[[#This Row],[IVA]] -> 3470.6736 | J61: =YEAR(Ventas_Wellpro4[[#This Row],[Fecha]]) -> 2025 | K61: =TEXT(Ventas_Wellpro4[[#This Row],[Fecha]],"MMMM") -> octubre | L61: =DAY(Ventas_Wellpro4[[#This Row],[Fecha]]) -> 1
B62: 45482 | C62: Termómetro Pediatrico Cute Animals Panda | D62: Walmart | E62: 70.05 | F62: 240 | G62: 2689.92 | H62: 16812 | I62: 19501.92 | J62: =YEAR(Ventas_Wellpro4[[#This Row],[Fecha]]) -> 2024 | K62: =TEXT(Ventas_Wellpro4[[#This Row],[Fecha]],"MMMM") -> julio | L62: =DAY(Ventas_Wellpro4[[#This Row],[Fecha]]) -> 9
B63: 45482 | C63: Termómetro Pediatrico Cute Animals Panda | D63: Walmart | E63: 70.05 | F63: 240 | G63: 2689.92 | H63: 16812 | I63: 19501.92 | J63: =YEAR(Ventas_Wellpro4[[#This Row],[Fecha]]) -> 2024 | K63: =TEXT(Ventas_Wellpro4[[#This Row],[Fecha]],"MMMM") -> julio | L63: =DAY(Ventas_Wellpro4[[#This Row],[Fecha]]) -> 9
B64: 45482 | C64: Termómetro Pediatrico Cute Animals Panda | D64: Walmart | E64: 70.05 | F64: 240 | G64: 2689.92 | H64: 16812 | I64: 19501.92 | J64: =YEAR(Ventas_Wellpro4[[#This Row],[Fecha]]) -> 2024 | K64: =TEXT(Ventas_Wellpro4[[#This Row],[Fecha]],"MMMM") -> julio | L64: =DAY(Ventas_Wellpro4[[#This Row],[Fecha]]) -> 9
B65: 45482 | C65: Termómetro Pediatrico Cute Animals Panda | D65: Walmart | E65: 70.05 | F65: 240 | G65: 2689.92 | H65: 16812 | I65: 19501.92 | J65: =YEAR(Ventas_Wellpro4[[#This Row],[Fecha]]) -> 2024 | K65: =TEXT(Ventas_Wellpro4[[#This Row],[Fecha]],"MMMM") -> julio | L65: =DAY(Ventas_Wellpro4[[#This Row],[Fecha]]) -> 9
B66: 45482 | C66: Termómetro Pediatrico Cute Animals Panda | D66: Walmart | E66: 70.05 | F66: 240 | G66: 2689.92 | H66: 16812 | I66: 19501.92 | J66: =YEAR(Ventas_Wellpro4[[#This Row],[Fecha]]) -> 2024 | K66: =TEXT(Ventas_Wellpro4[[#This Row],[Fecha]],"MMMM") -> julio | L66: =DAY(Ventas_Wellpro4[[#This Row],[Fecha]]) -> 9
B67: 45931 | C67: Nebulizador Adulto Walmart | D67: Walmart | E67: 498.66 | F67: 6 | G67: =+(Ventas_Wellpro4[[#This Row],[Precio de Venta]]*0.16)*Ventas_Wellpro4[[#This Row],[Cantidad Vendida]] -> 478.7136 | H67: 2991.96 | I67: =+Ventas_Wellpro4[[#This Row],[Total de Venta sin IVA]]+Ventas_Wellpro4[[#This Row],[IVA]] -> 3470.6736 | J67: =YEAR(Ventas_Wellpro4[[#This Row],[Fecha]]) -> 2025 | K67: =TEXT(Ventas_Wellpro4[[#This Row],[Fecha]],"MMMM") -> octubre | L67: =DAY(Ventas_Wellpro4[[#This Row],[Fecha]]) -> 1
B68: 45931 | C68: Termómetro Pediatrico Cute Animals Koala | D68: MERCADO LIBRE | E68: 137.79 | F68: 1 | G68: =+(Ventas_Wellpro4[[#This Row],[Precio de Venta]]*0.16)*Ventas_Wellpro4[[#This Row],[Cantidad Vendida]] -> 22.0464 | H68: 137.79 | I68: =+Ventas_Wellpro4[[#This Row],[Total de Venta sin IVA]]+Ventas_Wellpro4[[#This Row],[IVA]] -> 159.8364 | J68: =YEAR(Ventas_Wellpro4[[#This Row],[Fecha]]) -> 2025 | K68: =TEXT(Ventas_Wellpro4[[#This Row],[Fecha]],"MMMM") -> octubre | L68: =DAY(Ventas_Wellpro4[[#This Row],[Fecha]]) -> 1
B69: 45484 | C69: Termómetro Pediatrico Cute Animals Panda | D69: Walmart | E69: 70.05 | F69: 240 | G69: 2689.92 | H69: 16812 | I69: 19501.92 | J69: =YEAR(Ventas_Wellpro4[[#This Row],[Fecha]]) -> 2024 | K69: =TEXT(Ventas_Wellpro4[[#This Row],[Fecha]],"MMMM") -> julio | L69: =DAY(Ventas_Wellpro4[[#This Row],[Fecha]]) -> 11
B70: 45488 | C70: Termómetro Pediatrico Cute Animals Koala | D70: Amazon | E70: 93.01 | F70: 240 | G70: 3571.58 | H70: 22322.4 | I70: 25893.98 | J70: =YEAR(Ventas_Wellpro4[[#This Row],[Fecha]]) -> 2024 | K70: =TEXT(Ventas_Wellpro4[[#This Row],[Fecha]],"MMMM") -> julio | L70: =DAY(Ventas_Wellpro4[[#This Row],[Fecha]]) -> 15
B71: 45931 | C71: Termómetro Pediatrico Cute Animals Ranita | D71: MERCADO LIBRE | E71: 137.79 | F71: 1 | G71: =+(Ventas_Wellpro4[[#This Row],[Precio de Venta]]*0.16)*Ventas_Wellpro4[[#This Row],[Cantidad Vendida]] -> 22.0464 | H71: 137.79 | I71: =+Ventas_Wellpro4[[#This Row],[Total de Venta sin IVA]]+Ventas_Wellpro4[[#This Row],[IVA]] -> 159.8364 | J71: =YEAR(Ventas_Wellpro4[[#This Row],[Fecha]]) -> 2025 | K71: =TEXT(Ventas_Wellpro4[[#This Row],[Fecha]],"MMMM") -> octubre | L71: =DAY(Ventas_Wellpro4[[#This Row],[Fecha]]) -> 1
B72: 45931 | C72: Inodoro Portatil con tapa y brazo | D72: MERCADO LIBRE | E72: 1706.9 | F72: 1 | G72: =+(Ventas_Wellpro4[[#This Row],[Precio de Venta]]*0.16)*Ventas_Wellpro4[[#This Row],[Cantidad Vendida]] -> 273.104 | H72: 1706.9 | I72: =+Ventas_Wellpro4[[#This Row],[Total de Venta sin IVA]]+Ventas_Wellpro4[[#This Row],[IVA]] -> 1980.004 | J72: =YEAR(Ventas_Wellpro4[[#This Row],[Fecha]]) -> 2025 | K72: =TEXT(Ventas_Wellpro4[[#This Row],[Fecha]],"MMMM") -> octubre | L72: =DAY(Ventas_Wellpro4[[#This Row],[Fecha]]) -> 1
B73: 45931 | C73: Termómetro Pediatrico Cute Animals Cerdito | D73: MERCADO LIBRE | E73: 137.79 | F73: 1 | G73: =+(Ventas_Wellpro4[[#This Row],[Precio de Venta]]*0.16)*Ventas_Wellpro4[[#This Row],[Cantidad Vendida]] -> 22.0464 | H73: 137.79 | I73: =+Ventas_Wellpro4[[#This Row],[Total de Venta sin IVA]]+Ventas_Wellpro4[[#This Row],[IVA]] -> 159.8364 | J73: =YEAR(Ventas_Wellpro4[[#This Row],[Fecha]]) -> 2025 | K73: =TEXT(Ventas_Wellpro4[[#This Row],[Fecha]],"MMMM") -> octubre | L73: =DAY(Ventas_Wellpro4[[#This Row],[Fecha]]) -> 1
B74: 45912 | C74: Nebulizador Adulto Moderno NBA-10WA | D74: Mercado Libre | E74: 905.16 | F74: 1 | G74: 144.8256 | H74: 905.16 | I74: 1049.9856 | J74: =YEAR(Ventas_Wellpro4[[#This Row],[Fecha]]) -> 2025 | K74: =TEXT(Ventas_Wellpro4[[#This Row],[Fecha]],"MMMM") -> septiembre | L74: =DAY(Ventas_Wellpro4[[#This Row],[Fecha]]) -> 12
B75: 45931 | C75: Nebulizador Pediatrico Elefante Celeste | D75: Walmart | E75: 525.59 | F75: 24 | G75: =+(Ventas_Wellpro4[[#This Row],[Precio de Venta]]*0.16)*Ventas_Wellpro4[[#This Row],[Cantidad Vendida]] -> 2018.2656 | H75: 12614.16 | I75: =+Ventas_Wellpro4[[#This Row],[Total de Venta sin IVA]]+Ventas_Wellpro4[[#This Row],[IVA]] -> 14632.426 | J75: =YEAR(Ventas_Wellpro4[[#This Row],[Fecha]]) -> 2025 | K75: =TEXT(Ventas_Wellpro4[[#This Row],[Fecha]],"MMMM") -> octubre | L75: =DAY(Ventas_Wellpro4[[#This Row],[Fecha]]) -> 1
B76: 45931 | C76: Nebulizador Pediatrico Elefante Celeste | D76: Walmart | E76: 525.59 | F76: 102 | G76: =+(Ventas_Wellpro4[[#This Row],[Precio de Venta]]*0.16)*Ventas_Wellpro4[[#This Row],[Cantidad Vendida]] -> 8577.6288 | H76: 53610.18 | I76: =+Ventas_Wellpro4[[#This Row],[Total de Venta sin IVA]]+Ventas_Wellpro4[[#This Row],[IVA]] -> 62187.809 | J76: =YEAR(Ventas_Wellpro4[[#This Row],[Fecha]]) -> 2025 | K76: =TEXT(Ventas_Wellpro4[[#This Row],[Fecha]],"MMMM") -> octubre | L76: =DAY(Ventas_Wellpro4[[#This Row],[Fecha]]) -> 1
B77: 45931 | C77: Nebulizador Pediatrico Elefante Celeste | D77: Walmart | E77: 525.59 | F77: 54 | G77: =+(Ventas_Wellpro4[[#This Row],[Precio de Venta]]*0.16)*Ventas_Wellpro4[[#This Row],[Cantidad Vendida]] -> 4541.0976 | H77: 28381.86 | I77: =+Ventas_Wellpro4[[#This Row],[Total de Venta sin IVA]]+Ventas_Wellpro4[[#This Row],[IVA]] -> 32922.958 | J77: =YEAR(Ventas_Wellpro4[[#This Row],[Fecha]]) -> 2025 | K77: =TEXT(Ventas_Wellpro4[[#This Row],[Fecha]],"MMMM") -> octubre | L77: =DAY(Ventas_Wellpro4[[#This Row],[Fecha]]) -> 1
B78: 45931 | C78: Nebulizador Pediatrico Elefante Celeste | D78: Walmart | E78: 525.59 | F78: 66 | G78: =+(Ventas_Wellpro4[[#This Row],[Precio de Venta]]*0.16)*Ventas_Wellpro4[[#This Row],[Cantidad Vendida]] -> 5550.2304 | H78: 34688.94 | I78: =+Ventas_Wellpro4[[#This Row],[Total de Venta sin IVA]]+Ventas_Wellpro4[[#This Row],[IVA]] -> 40239.17 | J78: =YEAR(Ventas_Wellpro4[[#This Row],[Fecha]]) -> 2025 | K78: =TEXT(Ventas_Wellpro4[[#This Row],[Fecha]],"MMMM") -> octubre | L78: =DAY(Ventas_Wellpro4[[#This Row],[Fecha]]) -> 1
B79: 45931 | C79: Nebulizador Pediatrico Elefante Celeste | D79: Walmart | E79: 525.59 | F79: 60 | G79: =+(Ventas_Wellpro4[[#This Row],[Precio de Venta]]*0.16)*Ventas_Wellpro4[[#This Row],[Cantidad Vendida]] -> 5045.664 | H79: 31535.4 | I79: =+Ventas_Wellpro4[[#This Row],[Total de Venta sin IVA]]+Ventas_Wellpro4[[#This Row],[IVA]] -> 36581.064 | J79: =YEAR(Ventas_Wellpro4[[#This Row],[Fecha]]) -> 2025 | K79: =TEXT(Ventas_Wellpro4[[#This Row],[Fecha]],"MMMM") -> octubre | L79: =DAY(Ventas_Wellpro4[[#This Row],[Fecha]]) -> 1
B80: 45932 | C80: Nebulizador Adulto Walmart | D80: Walmart | E80: 498.66 | F80: 6 | G80: =+(Ventas_Wellpro4[[#This Row],[Precio de Venta]]*0.16)*Ventas_Wellpro4[[#This Row],[Cantidad Vendida]] -> 478.7136 | H80: 2991.96 | I80: =+Ventas_Wellpro4[[#This Row],[Total de Venta sin IVA]]+Ventas_Wellpro4[[#This Row],[IVA]] -> 3470.6736 | J80: =YEAR(Ventas_Wellpro4[[#This Row],[Fecha]]) -> 2025 | K80: =TEXT(Ventas_Wellpro4[[#This Row],[Fecha]],"MMMM") -> octubre | L80: =DAY(Ventas_Wellpro4[[#This Row],[Fecha]]) -> 2
B81: 45932 | C81: Nebulizador Adulto Walmart | D81: Walmart | E81: 498.66 | F81: 6 | G81: =+(Ventas_Wellpro4[[#This Row],[Precio de Venta]]*0.16)*Ventas_Wellpro4[[#This Row],[Cantidad Vendida]] -> 478.7136 | H81: 2991.96 | I81: =+Ventas_Wellpro4[[#This Row],[Total de Venta sin IVA]]+Ventas_Wellpro4[[#This Row],[IVA]] -> 3470.6736 | J81: =YEAR(Ventas_Wellpro4[[#This Row],[Fecha]]) -> 2025 | K81: =TEXT(Ventas_Wellpro4[[#This Row],[Fecha]],"MMMM") -> octubre | L81: =DAY(Ventas_Wellpro4[[#This Row],[Fecha]]) -> 2
B82: 45932 | C82: Nebulizador Adulto Walmart | D82: Walmart | E82: 498.66 | F82: 6 | G82: =+(Ventas_Wellpro4[[#This Row],[Precio de Venta]]*0.16)*Ventas_Wellpro4[[#This Row],[Cantidad Vendida]] -> 478.7136 | H82: 2991.96 | I82: =+Ventas_Wellpro4[[#This Row],[Total de Venta sin IVA]]+Ventas_Wellpro4[[#This Row],[IVA]] -> 3470.6736 | J82: =YEAR(Ventas_Wellpro4[[#This Row],[Fecha]]) -> 2025 | K82: =TEXT(Ventas_Wellpro4[[#This Row],[Fecha]],"MMMM") -> octubre | L82: =DAY(Ventas_Wellpro4[[#This Row],[Fecha]]) -> 2
B83: 45932 | C83: Nebulizador Adulto Walmart | D83: Walmart | E83: 498.66 | F83: 12 | G83: =+(Ventas_Wellpro4[[#This Row],[Precio de Venta]]*0.16)*Ventas_Wellpro4[[#This Row],[Cantidad Vendida]] -> 957.4272 | H83: 5983.92 | I83: =+Ventas_Wellpro4[[#This Row],[Total de Venta sin IVA]]+Ventas_Wellpro4[[#This Row],[IVA]] -> 6941.3472 | J83: =YEAR(Ventas_Wellpro4[[#This Row],[Fecha]]) -> 2025 | K83: =TEXT(Ventas_Wellpro4[[#This Row],[Fecha]],"MMMM") -> octubre | L83: =DAY(Ventas_Wellpro4[[#This Row],[Fecha]]) -> 2
...

Sheet Catalogo Clientes
A1: Clientes | B1: Categoría 2 | C1: Pais
A2: WALMART | B2: AUTOSERVICIO | C2: MEXICO | E2: =UPPER(Catalogo_Clientes[[#This Row],[Clientes]]) -> WALMART
A3: AMAZON | B3: E-COMERCE | C3: MEXICO | E3: =UPPER(Catalogo_Clientes[[#This Row],[Clientes]]) -> AMAZON
A4: MARKET PLACE | B4: E-COMERCE | C4: MEXICO | E4: =UPPER(Catalogo_Clientes[[#This Row],[Clientes]]) -> MARKET PLACE
A5: CHEDRAUI | B5: AUTOSERVICIO | C5: MEXICO | E5: =UPPER(Catalogo_Clientes[[#This Row],[Clientes]]) -> CHEDRAUI
A6: MEDICAL LIFE | B6: FARMACIA | C6: MEXICO | E6: =UPPER(Catalogo_Clientes[[#This Row],[Clientes]]) -> MEDICAL LIFE
A7: NADRO | B7: DISTRIBUIDOR | C7: MEXICO | E7: =UPPER(Catalogo_Clientes[[#This Row],[Clientes]]) -> NADRO
A8: UNEFARM | B8: FARMACIA | C8: MEXICO | E8: =UPPER(Catalogo_Clientes[[#This Row],[Clientes]]) -> UNEFARM
A9: FARMACIA SAN PABLO | B9: FARMACIA | C9: MEXICO | E9: =UPPER(Catalogo_Clientes[[#This Row],[Clientes]]) -> FARMACIA SAN PABLO
A10: FARMACIA SANA SANA | B10: FARMACIA | C10: MEXICO | E10: =UPPER(Catalogo_Clientes[[#This Row],[Clientes]]) -> FARMACIA SANA SANA
A11: FORTUS | B11: INTERNO | C11: MEXICO | E11: =UPPER(Catalogo_Clientes[[#This Row],[Clientes]]) -> FORTUS
A12: BASILICA DE GUADALUPE | B12: AUTOSERVICIO | C12: MEXICO | E12: =UPPER(Catalogo_Clientes[[#This Row],[Clientes]]) -> BASILICA DE GUADALUPE
A13: MERCADO LIBRE | B13: E-COMERCE | C13: MEXICO | E13: =UPPER(Catalogo_Clientes[[#This Row],[Clientes]]) -> MERCADO LIBRE
... A29: FARMACIA BENAVIDES | B29: FARMACIA | C29: MEXICO | E29: =UPPER(Catalogo_Clientes[[#This Row],[Clientes]]) -> FARMACIA BENAVIDES

Sheet TblProductos (2)
A3: Suma de Cantidad Vendida | C3: Años (Fecha) | D3: Trimestres (Fecha) | E3: Meses (Fecha) | F3: Fecha
C4: <30/01/2024 | D4: 2024 | E4: 2024 | F4: 2024 | G4: 2024 | H4: 2024 | I4: 2024 | J4: 2024 | K4: 2024 | L4: 2024 | M4: 2024 | N4: 2024 | O4: 2024 | P4: 2024 | Q4: 2024 | R4: 2024 | S4: 2024 | T4: 2024 | U4: 2024 | V4: 2024 | W4: 2024 | X4: 2024 | Y4: 2024 | Z4: 2024 | AA4: 2024 | AB4: 2024 | AC4: 2024 | AD4: 2024 | AE4: 2024 | AF4: 2024 | AG4: 2024 | AH4: 2024 | AI4: 2024 | AJ4: 2024 | AK4: 2024 | AL4: 2024 | AM4: 2024 | AN4: 2024 | AO4: 2024 | AP4: 2024 | AQ4: 2024 | AR4: 2024 | AS4: 2024 | AT4: 2024 | AU4: 2024 | AV4: 2024 | AW4: 2024 | AX4: 2024 | AY4: 2024 | AZ4: 2024 | BA4: 2024 | BB4: 2024 | BC4: 2024 | BD4: 2024 | BE4: 2024 | BF4: 2024 | BG4: 2024 | BH4: 2024 | BI4: 2024 | BJ4: 2024 | BK4: 2024 | BL4: 2024 | BM4: 2024 | BN4: 2024 | BO4: 2024 | BP4: 2024 | BQ4: 2024 | BR4: 2024 | BS4: 2024 | BT4: 2024 | BU4: 2024 | BV4: 2024 | BW4: 2024 | BX4: 2024 | BY4: 2024 | BZ4: 2024 | CA4: 2024 | CB4: 2024 | CC4: 2024 | CD4: 2024 | CE4: 2024 | CF4: 2024 | CG4: 2024 | CH4: 2024 | CI4: 2025 | CJ4: 2025 | CK4: 2025 | CL4: 2025 | CM4: 2025 | CN4: 2025 | CO4: 2025 | CP4: 2025 | CQ4: 2025 | CR4: 2025 | CS4: 2025 | CT4: 2025 | CU4: 2025 | CV4: 2025 | CW4: 2025 | CX4: 2025 | CY4: 2025 | CZ4: 2025 | DA4: 2025 | DB4: 2025 | DC4: 2025 | DD4: 2025 | DE4: 2025 | DF4: 2025 | DG4: 2025 | DH4: 2025 | DI4: 2025 | DJ4: 2025 | DK4: 2025 | DL4: 2025 | DM4: 2025 | DN4: 2025 | DO4: 2025 | DP4: 2025 | DQ4: 2025 | DR4: 2025 | DS4: 2025 | DT4: 2025 | DU4: 2025 | DV4: 2025 | DW4: 2025 | DX4: 2025 | DY4: 2025 | DZ4: 2025 | EA4: 2025 | EB4: 2025 | EC4: 2025 | ED4: 2025 | EE4: 2025 | EF4: 2025 | EG4: 2025 | EH4: 2025 | EI4: 2025 | EJ4: 2025 | EK4: 2025 | EL4: 2025 | EM4: 2025 | EN4: 2025 | EO4: 2025 | EP4: 2025 | EQ4: 2025 | ER4: 2025 | ES4: 2025 | ET4: 2025 | EU4: 2025 | EV4: 2025 | EW4: 2025 | EX4: 2025 | EY4: 2025 | EZ4: 2025 | FA4: 2025 | FB4: 2025 | FC4: 2025 | FD4: 2025 | FE4: 2025 | FF4: 2025 | FG4: 2025 | FH4: 2025 | FI4: 2025 | FJ4: 2025 | FK4: 2025 | FL4: 2025 | FM4: 2025 | FN4: 2025 | FO4: 2025 | FP4: 2025 | FQ4: 2025 | FR4: 2025 | FS4: 2025 | FT4: 2025 | FU4: 2025 | FV4: 2025 | FW4: 2025 | FX4: 2025 | FY4: 2025 | FZ4: 2025 | GA4: 2025 | GB4: 2025 | GC4: 2025 | GD4: 2025 | GE4: 2025 | GF4: 2025 | GG4: 2025 | GH4: 2025 | GI4: 2025 | GJ4: 2025 | GK4: 2025 | GL4: 2025 | GM4: 2025 | GN4: 2025 | GO4: 2025 | GP4: 2025 | GQ4: 2025 | GR4: 2025 | GS4: 2025 | GT4: 2025 | GU4: 2025 | GV4: 2025 | GW4: 2025 | GX4: 2025 | GY4: 2025 | GZ4: 2025 | HA4: 2025 | HB4: 2025 | HC4: 2025 | HD4: 2025 | HE4: 2025 | HF4: 2025 | HG4: 2025 | HH4: 2025 | HI4: 2025 | HJ4: 2025 | HK4: 2025 | HL4: 2025 | HM4: 2025 | HN4: 2025 | HO4: 2025 | HP4: 2025 | HQ4: 2025 | HR4: 2025 | HS4: 2025 | HT4: 2025 | HU4: 2025 | HV4: 2025 | HW4: 2025 | HX4: 2025 | HY4: 2025 | HZ4: 2025 | IA4: 2025 | IB4: 2025 | IC4: 2025 | ID4: 2025 | IE4: 2025 | IF4: 2025 | IG4: 2025 | IH4: 2025 | II4: 2025 | IJ4: 2025 | IK4: 2025 | IL4: 2025 | IM4: 2025 | IN4: 2025 | IO4: 2025 | IP4: 2025 | IQ4: 2025 | IR4: 2025 | IS4: 2025 | IT4: 2025 | IU4: 2025 | IV4: 2025 | IW4: 2025 | IX4: 2025 | IY4: 2025 | IZ4: 2025 | JA4: 2025 | JB4: 2025 | JC4: 2025 | JD4: 2025 | JE4: 2025 | JF4: 2025 | JG4: 2025 | JH4: 2025 | JI4: 2025 | JJ4: 2025 | JK4: 2025 | JL4: 2025 | JM4: 2025 | JN4: 2025 | JO4: 2025 | JP4: 2025 | JQ4: 2025 | JR4: 2025 | JS4: 2025 | JT4: 2025 | JU4: 2025 | JV4: 2025 | JW4: 2025 | JX4: 2025 | JY4: 2025 | JZ4: 2025 | KA4: 2025 | KB4: 2025 | KC4: 2025 | KD4: 2025 | KE4: 2025 | KF4: 2025 | KG4: 2025 | KH4: 2025 | KI4: 2025 | KJ4: 2025 | KK4: 2025 | KL4: 2025 | KM4: 2025 | KN4: 2025 | KO4: 2025 | KP4: 2025 | KQ4: 2025 | KR4: 2025 | KS4: 2025 | KT4: 2025 | KU4: 2025 | KV4: 2025 | KW4: 2026 | KX4: 2026 | KY4: 2026 | KZ4: 2026 | LA4: 2026 | LB4: 2026 | LC4: 2026 | LD4: 2026 | LE4: 2026 | LF4: 2026 | LG4: 2026 | LH4: 2026 | LI4: 2026 | LJ4: 2026 | LK4: 2026 | LL4: 2026 | LM4: 2026 | LN4: 2026 | LO4: 2026 | LP4: 2026 | LQ4: 2026 | LR4: 2026 | LS4: 2026 | LT4: 2026 | LU4: 2026 | LV4: 2026 | LW4: 2026 | LX4: 2026 | LY4: 2026 | LZ4: 2026 | MA4: 2026 | MB4: 2026 | MC4: 2026 | MD4: 2026 | ME4: 2026 | MF4: 2026 | MG4: 2026 | MH4: 2026 | MI4: 2026 | MJ4: 2026 | MK4: 2026 | ML4: 2026 | MM4: 2026 | MN4: 2026 | MO4: 2026 | MP4: 2026 | MQ4: 2026 | MR4: 2026 | MS4: 2026 | MT4: 2026 | MU4: 2026 | MV4: 2026 | MW4: 2026 | MX4: 2026 | MY4: 2026 | MZ4: 2026 | NA4: 2026 | NB4: 2026 | NC4: 2026 | ND4: 2026 | NE4: 2026 | NF4: 2026 | NG4: 2026 | NH4: 2026 | NI4: 2026 | NJ4: 2026 | NK4: 2026 | NL4: 2026 | NM4: 2026 | NN4: 2026 | NO4: 2026 | NP4: 2026 | NQ4: 2026 | NR4: 2026 | NS4: 2026 | NT4: 2026 | NU4: 2026 | NV4: 2026 | NW4: 2026 | NX4: 2026 | NY4: 2026 | NZ4: 2026 | OA4: 2026 | OB4: 2026 | OC4: 2026 | OD4: 2026 | OE4: 2026 | OF4: 2026 | OG4: 2026 | OH4: 2026 | OI4: 2026 | OJ4: 2026 | OK4: 2026 | OL4: 2026 | OM4: 2026 | ON4: 2026 | OO4: 2026 | OP4: 2026 | OQ4: 2026 | OR4: 2026 | OS4: 2026 | OT4: 2026 | OU4: 2026 | OV4: 2026 | OW4: 2026 | OX4: 2026 | OY4: 2026 | OZ4: 2026 | PA4: 2026 | PB4: 2026 | PC4: 2026 | PD4: 2026 | PE4: 2026 | PF4: 2026 | PG4: 2026 | PH4: 2026 | PI4: 2026 | PJ4: 2026 | PK4: 2026 | PL4: 2026 | PM4: 2026 | PN4: 2026 | PO4: 2026 | PP4: 2026 | PQ4: 2026 | PR4: 2026 | PS4: 2026 | PT4: 2026 | PU4: 2026 | PV4: 2026 | PW4: 2026 | PX4: 2026 | PY4: 2026 | PZ4: 2026 | QA4: 2026 | QB4: 2026 | QC4: 2026 | QD4: 2026 | QE4: 2026 | QF4: 2026 | QG4: 2026 | QH4: 2026 | QI4: 2026 | QJ4: 2026 | QK4: 2026 | QL4: 2026 | QM4: 2026 | QN4: 2026 | QO4: 2026 | QP4: 2026 | QQ4: 2026 | QR4: 2026 | QS4: 2026 | QT4: 2026 | QU4: 2026 | QV4: 2026 | QW4: 2026 | QX4: 2026 | QY4: 2026 | QZ4: 2026 | RA4: 2026
C5: <30/01/2024 | D5: Trim.1 | E5: Trim.1 | F5: Trim.1 | G5: Trim.1 | H5: Trim.2 | I5: Trim.2 | J5: Trim.2 | K5: Trim.2 | L5: Trim.2 | M5: Trim.2 | N5: Trim.3 | O5: Trim.3 | P5: Trim.3 | Q5: Trim.3 | R5: Trim.3 | S5: Trim.3 | T5: Trim.3 | U5: Trim.3 | V5: Trim.3 | W5: Trim.3 | X5: Trim.3 | Y5: Trim.3 | Z5: Trim.3 | AA5: Trim.3 | AB5: Trim.3 | AC5: Trim.3 | AD5: Trim.3 | AE5: Trim.3 | AF5: Trim.3 | AG5: Trim.3 | AH5: Trim.3 | AI5: Trim.3 | AJ5: Trim.3 | AK5: Trim.3 | AL5: Trim.3 | AM5: Trim.3 | AN5: Trim.3 | AO5: Trim.3 | AP5: Trim.3 | AQ5: Trim.3 | AR5: Trim.4 | AS5: Trim.4 | AT5: Trim.4 | AU5: Trim.4 | AV5: Trim.4 | AW5: Trim.4 | AX5: Trim.4 | AY5: Trim.4 | AZ5: Trim.4 | BA5: Trim.4 | BB5: Trim.4 | BC5: Trim.4 | BD5: Trim.4 | BE5: Trim.4 | BF5: Trim.4 | BG5: Trim.4 | BH5: Trim.4 | BI5: Trim.4 | BJ5: Trim.4 | BK5: Trim.4 | BL5: Trim.4 | BM5: Trim.4 | BN5: Trim.4 | BO5: Trim.4 | BP5: Trim.4 | BQ5: Trim.4 | BR5: Trim.4 | BS5: Trim.4 | BT5: Trim.4 | BU5: Trim.4 | BV5: Trim.4 | BW5: Trim.4 | BX5: Trim.4 | BY5: Trim.4 | BZ5: Trim.4 | CA5: Trim.4 | CB5: Trim.4 | CC5: Trim.4 | CD5: Trim.4 | CE5: Trim.4 | CF5: Trim.4 | CG5: Trim.4 | CH5: Trim.4 | CI5: Trim.1 | CJ5: Trim.1 | CK5: Trim.1 | CL5: Trim.1 | CM5: Trim.1 | CN5: Trim.1 | CO5: Trim.1 | CP5: Trim.1 | CQ5: Trim.1 | CR5: Trim.1 | CS5: Trim.1 | CT5: Trim.1 | CU5: Trim.1 | CV5: Trim.1 | CW5: Trim.1 | CX5: Trim.1 | CY5: Trim.1 | CZ5: Trim.1 | DA5: Trim.1 | DB5: Trim.1 | DC5: Trim.1 | DD5: Trim.1 | DE5: Trim.1 | DF5: Trim.1 | DG5: Trim.1 | DH5: Trim.1 | DI5: Trim.1 | DJ5: Trim.1 | DK5: Trim.1 | DL5: Trim.1 | DM5: Trim.1 | DN5: Trim.1 | DO5: Trim.1 | DP5: Trim.1 | DQ5: Trim.1 | DR5: Trim.1 | DS5: Trim.1 | DT5: Trim.1 | DU5: Trim.1 | DV5: Trim.1 | DW5: Trim.1 | DX5: Trim.1 | DY5: Trim.1 | DZ5: Trim.1 | EA5: Trim.1 | EB5: Trim.1 | EC5: Trim.1 | ED5: Trim.1 | EE5: Trim.1 | EF5: Trim.1 | EG5: Trim.1 | EH5: Trim.1 | EI5: Trim.1 | EJ5: Trim.2 | EK5: Trim.2 | EL5: Trim.2 | EM5: Trim.2 | EN5: Trim.2 | EO5: Trim.2 | EP5: Trim.2 | EQ5: Trim.2 | ER5: Trim.2 | ES5: Trim.2 | ET5: Trim.2 | EU5: Trim.2 | EV5: Trim.2 | EW5: Trim.2 | EX5: Trim.2 | EY5: Trim.2 | EZ5: Trim.2 | FA5: Trim.2 | FB5: Trim.2 | FC5: Trim.2 | FD5: Trim.2 | FE5: Trim.2 | FF5: Trim.2 | FG5: Trim.2 | FH5: Trim.2 | FI5: Trim.2 | FJ5: Trim.2 | FK5: Trim.2 | FL5: Trim.2 | FM5: Trim.2 | FN5: Trim.2 | FO5: Trim.2 | FP5: Trim.2 | FQ5: Trim.2 | FR5: Trim.2 | FS5: Trim.2 | FT5: Trim.2 | FU5: Trim.2 | FV5: Trim.2 | FW5: Trim.2 | FX5: Trim.2 | FY5: Trim.2 | FZ5: Trim.2 | GA5: Trim.2 | GB5: Trim.2 | GC5: Trim.2 | GD5: Trim.2 | GE5: Trim.2 | GF5: Trim.2 | GG5: Trim.2 | GH5: Trim.3 | GI5: Trim.3 | GJ5: Trim.3 | GK5: Trim.3 | GL5: Trim.3 | GM5: Trim.3 | GN5: Trim.3 | GO5: Trim.3 | GP5: Trim.3 | GQ5: Trim.3 | GR5: Trim.3 | GS5: Trim.3 | GT5: Trim.3 | GU5: Trim.3 | GV5: Trim.3 | GW5: Trim.3 | GX5: Trim.3 | GY5: Trim.3 | GZ5: Trim.3 | HA5: Trim.3 | HB5: Trim.3 | HC5: Trim.3 | HD5: Trim.3 | HE5: Trim.3 | HF5: Trim.3 | HG5: Trim.3 | HH5: Trim.3 | HI5: Trim.3 | HJ5: Trim.3 | HK5: Trim.3 | HL5: Trim.3 | HM5: Trim.3 | HN5: Trim.3 | HO5: Trim.3 | HP5: Trim.3 | HQ5: Trim.3 | HR5: Trim.3 | HS5: Trim.3 | HT5: Trim.3 | HU5: Trim.3 | HV5: Trim.3 | HW5: Trim.3 | HX5: Trim.3 | HY5: Trim.3 | HZ5: Trim.3 | IA5: Trim.3 | IB5: Trim.3 | IC5: Trim.3 | ID5: Trim.3 | IE5: Trim.3 | IF5: Trim.3 | IG5: Trim.3 | IH5: Trim.3 | II5: Trim.3 | IJ5: Trim.3 | IK5: Trim.3 | IL5: Trim.3 | IM5: Trim.3 | IN5: Trim.4 | IO5: Trim.4 | IP5: Trim.4 | IQ5: Trim.4 | IR5: Trim.4 | IS5: Trim.4 | IT5: Trim.4 | IU5: Trim.4 | IV5: Trim.4 | IW5: Trim.4 | IX5: Trim.4 | IY5: Trim.4 | IZ5: Trim.4 | JA5: Trim.4 | JB5: Trim.4 | JC5: Trim.4 | JD5: Trim.4 | JE5: Trim.4 | JF5: Trim.4 | JG5: Trim.4 | JH5: Trim.4 | JI5: Trim.4 | JJ5: Trim.4 | JK5: Trim.4 | JL5: Trim.4 | JM5: Trim.4 | JN5: Trim.4 | JO5: Trim.4 | JP5: Trim.4 | JQ5: Trim.4 | JR5: Trim.4 | JS5: Trim.4 | JT5: Trim.4 | JU5: Trim.4 | JV5: Trim.4 | JW5: Trim.4 | JX5: Trim.4 | JY5: Trim.4 | JZ5: Trim.4 | KA5: Trim.4 | KB5: Trim.4 | KC5: Trim.4 | KD5: Trim.4 | KE5: Trim.4 | KF5: Trim.4 | KG5: Trim.4 | KH5: Trim.4 | KI5: Trim.4 | KJ5: Trim.4 | KK5: Trim.4 | KL5: Trim.4 | KM5: Trim.4 | KN5: Trim.4 | KO5: Trim.4 | KP5: Trim.4 | KQ5: Trim.4 | KR5: Trim.4 | KS5: Trim.4 | KT5: Trim.4 | KU5: Trim.4 | KV5: Trim.4 | KW5: Trim.1 | KX5: Trim.1 | KY5: Trim.1 | KZ5: Trim.1 | LA5: Trim.1 | LB5: Trim.1 | LC5: Trim.1 | LD5: Trim.1 | LE5: Trim.1 | LF5: Trim.1 | LG5: Trim.1 | LH5: Trim.1 | LI5: Trim.1 | LJ5: Trim.1 | LK5: Trim.1 | LL5: Trim.1 | LM5: Trim.1 | LN5: Trim.1 | LO5: Trim.1 | LP5: Trim.1 | LQ5: Trim.1 | LR5: Trim.1 | LS5: Trim.1 | LT5: Trim.1 | LU5: Trim.1 | LV5: Trim.1 | LW5: Trim.1 | LX5: Trim.1 | LY5: Trim.1 | LZ5: Trim.1 | MA5: Trim.1 | MB5: Trim.1 | MC5: Trim.1 | MD5: Trim.1 | ME5: Trim.1 | MF5: Trim.1 | MG5: Trim.1 | MH5: Trim.1 | MI5: Trim.1 | MJ5: Trim.1 | MK5: Trim.1 | ML5: Trim.1 | MM5: Trim.1 | MN5: Trim.1 | MO5: Trim.1 | MP5: Trim.1 | MQ5: Trim.1 | MR5: Trim.1 | MS5: Trim.1 | MT5: Trim.1 | MU5: Trim.1 | MV5: Trim.1 | MW5: Trim.1 | MX5: Trim.1 | MY5: Trim.1 | MZ5: Trim.1 | NA5: Trim.1 | NB5: Trim.1 | NC5: Trim.1 | ND5: Trim.2 | NE5: Trim.2 | NF5: Trim.2 | NG5: Trim.2 | NH5: Trim.2 | NI5: Trim.2 | NJ5: Trim.2 | NK5: Trim.2 | NL5: Trim.2 | NM5: Trim.2 | NN5: Trim.2 | NO5: Trim.2 | NP5: Trim.2 | NQ5: Trim.2 | NR5: Trim.2 | NS5: Trim.2 | NT5: Trim.2 | NU5: Trim.2 | NV5: Trim.2 | NW5: Trim.2 | NX5: Trim.2 | NY5: Trim.2 | NZ5: Trim.2 | OA5: Trim.2 | OB5: Trim.2 | OC5: Trim.2 | OD5: Trim.2 | OE5: Trim.2 | OF5: Trim.2 | OG5: Trim.2 | OH5: Trim.2 | OI5: Trim.2 | OJ5: Trim.2 | OK5: Trim.2 | OL5: Trim.2 | OM5: Trim.2 | ON5: Trim.2 | OO5: Trim.2 | OP5: Trim.2 | OQ5: Trim.2 | OR5: Trim.2 | OS5: Trim.2 | OT5: Trim.2 | OU5: Trim.2 | OV5: Trim.2 | OW5: Trim.2 | OX5: Trim.2 | OY5: Trim.2 | OZ5: Trim.2 | PA5: Trim.2 | PB5: Trim.2 | PC5: Trim.2 | PD5: Trim.2 | PE5: Trim.2 | PF5: Trim.2 | PG5: Trim.2 | PH5: Trim.2 | PI5: Trim.2 | PJ5: Trim.2 | PK5: Trim.3 | PL5: Trim.3 | PM5: Trim.3 | PN5: Trim.3 | PO5: Trim.3 | PP5: Trim.3 | PQ5: Trim.3 | PR5: Trim.3 | PS5: Trim.3 | PT5: Trim.3 | PU5: Trim.3 | PV5: Trim.3 | PW5: Trim.3 | PX5: Trim.3 | PY5: Trim.3 | PZ5: Trim.3 | QA5: Trim.3 | QB5: Trim.3 | QC5: Trim.3 | QD5: Trim.3 | QE5: Trim.3 | QF5: Trim.3 | QG5: Trim.3 | QH5: Trim.3 | QI5: Trim.3 | QJ5: Trim.3 | QK5: Trim.3 | QL5: Trim.3 | QM5: Trim.3 | QN5: Trim.3 | QO5: Trim.3 | QP5: Trim.3 | QQ5: Trim.3 | QR5: Trim.3 | QS5: Trim.3 | QT5: Trim.3 | QU5: Trim.3 | QV5: Trim.3 | QW5: Trim.3 | QX5: Trim.3 | QY5: Trim.3 | QZ5: Trim.3 | RA5: Trim.3
C6: <30/01/2024 | D6: ene | E6: feb | F6: feb | G6: feb | H6: abr | I6: may | J6: may | K6: may | L6: jun | M6: jun | N6: jul | O6: jul | P6: jul | Q6: jul | R6: jul | S6: jul | T6: jul | U6: jul | V6: jul | W6: jul | X6: ago | Y6: ago | Z6: ago | AA6: ago | AB6: ago | AC6: ago | AD6: ago | AE6: ago | AF6: ago | AG6: sept | AH6: sept | AI6: sept | AJ6: sept | AK6: sept | AL6: sept | AM6: sept | AN6: sept | AO6: sept | AP6: sept | AQ6: sept | AR6: oct | AS6: oct | AT6: oct | AU6: oct | AV6: oct | AW6: oct | AX6: oct | AY6: oct | AZ6: oct | BA6: oct | BB6: oct | BC6: oct | BD6: oct | BE6: oct | BF6: oct | BG6: nov | BH6: nov | BI6: nov | BJ6: nov | BK6: nov | BL6: nov | BM6: nov | BN6: nov | BO6: nov | BP6: nov | BQ6: nov | BR6: nov | BS6: nov | BT6: nov | BU6: dic | BV6: dic | BW6: dic | BX6: dic | BY6: dic | BZ6: dic | CA6: dic | CB6: dic | CC6: dic | CD6: dic | CE6: dic | CF6: dic | CG6: dic | CH6: dic | CI6: ene | CJ6: ene | CK6: ene | CL6: ene | CM6: ene | CN6: ene | CO6: ene | CP6: ene | CQ6: ene | CR6: ene | CS6: ene | CT6: ene | CU6: ene | CV6: ene | CW6: ene | CX6: ene | CY6: ene | CZ6: feb | DA6: feb | DB6: feb | DC6: feb | DD6: feb | DE6: feb | DF6: feb | DG6: feb | DH6: feb | DI6: feb | DJ6: feb | DK6: feb | DL6: feb | DM6: feb | DN6: feb | DO6: feb | DP6: feb | DQ6: feb | DR6: mar | DS6: mar | DT6: mar | DU6: mar | DV6: mar | DW6: mar | DX6: mar | DY6: mar | DZ6: mar | EA6: mar | EB6: mar | EC6: mar | ED6: mar | EE6: mar | EF6: mar | EG6: mar | EH6: mar | EI6: mar | EJ6: abr | EK6: abr | EL6: abr | EM6: abr | EN6: abr | EO6: abr | EP6: abr | EQ6: abr | ER6: abr | ES6: abr | ET6: abr | EU6: abr | EV6: abr | EW6: abr | EX6: may | EY6: may | EZ6: may | FA6: may | FB6: may | FC6: may | FD6: may | FE6: may | FF6: may | FG6: may | FH6: may | FI6: may | FJ6: may | FK6: may | FL6: may | FM6: may | FN6: may | FO6: jun | FP6: jun | FQ6: jun | FR6: jun | FS6: jun | FT6: jun | FU6: jun | FV6: jun | FW6: jun | FX6: jun | FY6: jun | FZ6: jun | GA6: jun | GB6: jun | GC6: jun | GD6: jun | GE6: jun | GF6: jun | GG6: jun | GH6: jul | GI6: jul | GJ6: jul | GK6: jul | GL6: jul | GM6: jul | GN6: jul | GO6: jul | GP6: jul | GQ6: jul | GR6: jul | GS6: jul | GT6: jul | GU6: jul | GV6: jul | GW6: jul | GX6: jul | GY6: jul | GZ6: jul | HA6: jul | HB6: ago | HC6: ago | HD6: ago | HE6: ago | HF6: ago | HG6: ago | HH6: ago | HI6: ago | HJ6: ago | HK6: ago | HL6: ago | HM6: ago | HN6: ago | HO6: ago | HP6: ago | HQ6: ago | HR6: ago | HS6: ago | HT6: ago | HU6: sept | HV6: sept | HW6: sept | HX6: sept | HY6: sept | HZ6: sept | IA6: sept | IB6: sept | IC6: sept | ID6: sept | IE6: sept | IF6: sept | IG6: sept | IH6: sept | II6: sept | IJ6: sept | IK6: sept | IL6: sept | IM6: sept | IN6: oct | IO6: oct | IP6: oct | IQ6: oct | IR6: oct | IS6: oct | IT6: oct | IU6: oct | IV6: oct | IW6: oct | IX6: oct | IY6: oct | IZ6: oct | JA6: oct | JB6: oct | JC6: oct | JD6: oct | JE6: oct | JF6: oct | JG6: oct | JH6: nov | JI6: nov | JJ6: nov | JK6: nov | JL6: nov | JM6: nov | JN6: nov | JO6: nov | JP6: nov | JQ6: nov | JR6: nov | JS6: nov | JT6: nov | JU6: nov | JV6: nov | JW6: nov | JX6: nov | JY6: nov | JZ6: nov | KA6: nov | KB6: dic | KC6: dic | KD6: dic | KE6: dic | KF6: dic | KG6: dic | KH6: dic | KI6: dic | KJ6: dic | KK6: dic | KL6: dic | KM6: dic | KN6: dic | KO6: dic | KP6: dic | KQ6: dic | KR6: dic | KS6: dic | KT6: dic | KU6: dic | KV6: dic | KW6: ene | KX6: ene | KY6: ene | KZ6: ene | LA6: ene | LB6: ene | LC6: ene | LD6: ene | LE6: ene | LF6: ene | LG6: ene | LH6: ene | LI6: ene | LJ6: ene | LK6: ene | LL6: ene | LM6: ene | LN6: ene | LO6: ene | LP6: ene | LQ6: feb | LR6: feb | LS6: feb | LT6: feb | LU6: feb | LV6: feb | LW6: feb | LX6: feb | LY6: feb | LZ6: feb | MA6: feb | MB6: feb | MC6: feb | MD6: feb | ME6: feb | MF6: feb | MG6: feb | MH6: feb | MI6: feb | MJ6: mar | MK6: mar | ML6: mar | MM6: mar | MN6: mar | MO6: mar | MP6: mar | MQ6: mar | MR6: mar | MS6: mar | MT6: mar | MU6: mar | MV6: mar | MW6: mar | MX6: mar | MY6: mar | MZ6: mar | NA6: mar | NB6: mar | NC6: mar | ND6: abr | NE6: abr | NF6: abr | NG6: abr | NH6: abr | NI6: abr | NJ6: abr | NK6: abr | NL6: abr | NM6: abr | NN6: abr | NO6: abr | NP6: abr | NQ6: abr | NR6: abr | NS6: abr | NT6: abr | NU6: abr | NV6: abr | NW6: abr | NX6: may | NY6: may | NZ6: may | OA6: may | OB6: may | OC6: may | OD6: may | OE6: may | OF6: may | OG6: may | OH6: may | OI6: may | OJ6: may | OK6: may | OL6: may | OM6: may | ON6: may | OO6: may | OP6: may | OQ6: jun | OR6: jun | OS6: jun | OT6: jun | OU6: jun | OV6: jun | OW6: jun | OX6: jun | OY6: jun | OZ6: jun | PA6: jun | PB6: jun | PC6: jun | PD6: jun | PE6: jun | PF6: jun | PG6: jun | PH6: jun | PI6: jun | PJ6: jun | PK6: jul | PL6: jul | PM6: jul | PN6: jul | PO6: jul | PP6: jul | PQ6: jul | PR6: jul | PS6: jul | PT6: jul | PU6: jul | PV6: jul | PW6: jul | PX6: jul | PY6: jul | PZ6: jul | QA6: jul | QB6: jul | QC6: jul | QD6: jul | QE6: jul | QF6: jul | QG6: ago | QH6: ago | QI6: ago | QJ6: ago | QK6: ago | QL6: ago | QM6: ago | QN6: ago | QO6: ago | QP6: ago | QQ6: ago | QR6: ago | QS6: ago | QT6: ago | QU6: ago | QV6: ago | QW6: ago | QX6: ago | QY6: ago | QZ6: ago | RA6: ago
A7: Cliente | B7: Producto | C7: (en blanco) | D7: 45321 | E7: 45324 | F7: 45329 | G7: 45335 | H7: 45398 | I7: 45418 | J7: 45419 | K7: 45426 | L7: 45449 | M7: 45460 | N7: 45475 | O7: 45478 | P7: 45482 | Q7: 45484 | R7: 45488 | S7: 45490 | T7: 45492 | U7: 45499 | V7: 45503 | W7: 45504 | X7: 45505 | Y7: 45511 | Z7: 45512 | AA7: 45516 | AB7: 45517 | AC7: 45520 | AD7: 45527 | AE7: 45530 | AF7: 45532 | AG7: 45537 | AH7: 45538 | AI7: 45541 | AJ7: 45546 | AK7: 45547 | AL7: 45548 | AM7: 45552 | AN7: 45558 | AO7: 45560 | AP7: 45562 | AQ7: 45565 | AR7: 45568 | AS7: 45573 | AT7: 45574 | AU7: 45575 | AV7: 45579 | AW7: 45580 | AX7: 45581 | AY7: 45582 | AZ7: 45586 | BA7: 45587 | BB7: 45590 | BC7: 45593 | BD7: 45594 | BE7: 45595 | BF7: 45596 | BG7: 45600 | BH7: 45601 | BI7: 45603 | BJ7: 45604 | BK7: 45607 | BL7: 45608 | BM7: 45610 | BN7: 45611 | BO7: 45615 | BP7: 45616 | BQ7: 45617 | BR7: 45621 | BS7: 45622 | BT7: 45624 | BU7: 45628 | BV7: 45629 | BW7: 45630 | BX7: 45631 | BY7: 45635 | BZ7: 45636 | CA7: 45637 | CB7: 45638 | CC7: 45639 | CD7: 45643 | CE7: 45645 | CF7: 45652 | CG7: 45656 | CH7: 45657 | CI7: 45659 | CJ7: 45660 | CK7: 45663 | CL7: 45664 | CM7: 45665 | CN7: 45666 | CO7: 45670 | CP7: 45671 | CQ7: 45672 | CR7: 45673 | CS7: 45674 | CT7: 45677 | CU7: 45679 | CV7: 45684 | CW7: 45685 | CX7: 45686 | CY7: 45687 | CZ7: 45692 | DA7: 45693 | DB7: 45694 | DC7: 45695 | DD7: 45698 | DE7: 45699 | DF7: 45700 | DG7: 45701 | DH7: 45702 | DI7: 45705 | DJ7: 45706 | DK7: 45707 | DL7: 45708 | DM7: 45712 | DN7: 45713 | DO7: 45714 | DP7: 45715 | DQ7: 45716 | DR7: 45719 | DS7: 45720 | DT7: 45721 | DU7: 45722 | DV7: 45726 | DW7: 45727 | DX7: 45728 | DY7: 45729 | DZ7: 45730 | EA7: 45734 | EB7: 45735 | EC7: 45736 | ED7: 45737 | EE7: 45740 | EF7: 45741 | EG7: 45742 | EH7: 45743 | EI7: 45747 | EJ7: 45749 | EK7: 45750 | EL7: 45755 | EM7: 45757 | EN7: 45758 | EO7: 45762 | EP7: 45763 | EQ7: 45768 | ER7: 45769 | ES7: 45770 | ET7: 45771 | EU7: 45775 | EV7: 45776 | EW7: 45777 | EX7: 45782 | EY7: 45785 | EZ7: 45789 | FA7: 45790 | FB7: 45792 | FC7: 45793 | FD7: 45796 | FE7: 45797 | FF7: 45798 | FG7: 45799 | FH7: 45800 | FI7: 45803 | FJ7: 45804 | FK7: 45805 | FL7: 45806 | FM7: 45807 | FN7: 45808 | FO7: 45810 | FP7: 45811 | FQ7: 45812 | FR7: 45813 | FS7: 45814 | FT7: 45817 | FU7: 45818 | FV7: 45819 | FW7: 45820 | FX7: 45821 | FY7: 45824 | FZ7: 45825 | GA7: 45826 | GB7: 45827 | GC7: 45828 | GD7: 45831 | GE7: 45834 | GF7: 45835 | GG7: 45838 | GH7: 45839 | GI7: 45840 | GJ7: 45841 | GK7: 45845 | GL7: 45846 | GM7: 45847 | GN7: 45848 | GO7: 45852 | GP7: 45853 | GQ7: 45854 | GR7: 45856 | GS7: 45859 | GT7: 45860 | GU7: 45861 | GV7: 45862 | GW7: 45863 | GX7: 45866 | GY7: 45867 | GZ7: 45868 | HA7: 45869 | HB7: 45873 | HC7: 45874 | HD7: 45875 | HE7: 45876 | HF7: 45877 | HG7: 45880 | HH7: 45881 | HI7: 45882 | HJ7: 45883 | HK7: 45884 | HL7: 45887 | HM7: 45888 | HN7: 45889 | HO7: 45890 | HP7: 45891 | HQ7: 45894 | HR7: 45896 | HS7: 45897 | HT7: 45898 | HU7: 45901 | HV7: 45902 | HW7: 45903 | HX7: 45904 | HY7: 45905 | HZ7: 45908 | IA7: 45910 | IB7: 45911 | IC7: 45912 | ID7: 45915 | IE7: 45917 | IF7: 45918 | IG7: 45919 | IH7: 45922 | II7: 45923 | IJ7: 45924 | IK7: 45925 | IL7: 45929 | IM7: 45930 | IN7: 45931 | IO7: 45932 | IP7: 45933 | IQ7: 45936 | IR7: 45937 | IS7: 45938 | IT7: 45939 | IU7: 45940 | IV7: 45943 | IW7: 45944 | IX7: 45945 | IY7: 45946 | IZ7: 45947 | JA7: 45951 | JB7: 45952 | JC7: 45953 | JD7: 45957 | JE7: 45958 | JF7: 45959 | JG7: 45960 | JH7: 45964 | JI7: 45965 | JJ7: 45966 | JK7: 45967 | JL7: 45968 | JM7: 45971 | JN7: 45972 | JO7: 45973 | JP7: 45974 | JQ7: 45975 | JR7: 45978 | JS7: 45979 | JT7: 45980 | JU7: 45981 | JV7: 45982 | JW7: 45985 | JX7: 45986 | JY7: 45987 | JZ7: 45988 | KA7: 45989 | KB7: 45992 | KC7: 45993 | KD7: 45994 | KE7: 45995 | KF7: 45996 | KG7: 45999 | KH7: 46001 | KI7: 46002 | KJ7: 46003 | KK7: 46006 | KL7: 46007 | KM7: 46008 | KN7: 46009 | KO7: 46010 | KP7: 46013 | KQ7: 46014 | KR7: 46015 | KS7: 46017 | KT7: 46020 | KU7: 46021 | KV7: 46022 | KW7: 46024 | KX7: 46027 | KY7: 46028 | KZ7: 46029 | LA7: 46030 | LB7: 46031 | LC7: 46034 | LD7: 46035 | LE7: 46036 | LF7: 46037 | LG7: 46038 | LH7: 46041 | LI7: 46043 | LJ7: 46044 | LK7: 46045 | LL7: 46048 | LM7: 46049 | LN7: 46050 | LO7: 46051 | LP7: 46052 | LQ7: 46056 | LR7: 46057 | LS7: 46058 | LT7: 46059 | LU7: 46062 | LV7: 46063 | LW7: 46064 | LX7: 46065 | LY7: 46066 | LZ7: 46069 | MA7: 46070 | MB7: 46071 | MC7: 46072 | MD7: 46073 | ME7: 46076 | MF7: 46077 | MG7: 46078 | MH7: 46079 | MI7: 46080 | MJ7: 46083 | MK7: 46084 | ML7: 46085 | MM7: 46086 | MN7: 46087 | MO7: 46090 | MP7: 46091 | MQ7: 46092 | MR7: 46093 | MS7: 46094 | MT7: 46098 | MU7: 46099 | MV7: 46100 | MW7: 46101 | MX7: 46104 | MY7: 46105 | MZ7: 46106 | NA7: 46108 | NB7: 46111 | NC7: 46112 | ND7: 46113 | NE7: 46118 | NF7: 46119 | NG7: 46120 | NH7: 46121 | NI7: 46122 | NJ7: 46125 | NK7: 46126 | NL7: 46127 | NM7: 46128 | NN7: 46129 | NO7: 46132 | NP7: 46133 | NQ7: 46134 | NR7: 46135 | NS7: 46136 | NT7: 46139 | NU7: 46140 | NV7: 46141 | NW7: 46142 | NX7: 46146 | NY7: 46147 | NZ7: 46148 | OA7: 46149 | OB7: 46150 | OC7: 46153 | OD7: 46155 | OE7: 46156 | OF7: 46157 | OG7: 46160 | OH7: 46161 | OI7: 46162 | OJ7: 46163 | OK7: 46164 | OL7: 46167 | OM7: 46168 | ON7: 46169 | OO7: 46170 | OP7: 46171 | OQ7: 46174 | OR7: 46175 | OS7: 46176 | OT7: 46177 | OU7: 46178 | OV7: 46181 | OW7: 46182 | OX7: 46183 | OY7: 46184 | OZ7: 46188 | PA7: 46189 | PB7: 46190 | PC7: 46192 | PD7: 46195 | PE7: 46196 | PF7: 46197 | PG7: 46198 | PH7: 46199 | PI7: 46202 | PJ7: 46203 | PK7: 46204 | PL7: 46205 | PM7: 46206 | PN7: 46209 | PO7: 46210 | PP7: 46211 | PQ7: 46212 | PR7: 46213 | PS7: 46216 | PT7: 46217 | PU7: 46218 | PV7: 46219 | PW7: 46220 | PX7: 46223 | PY7: 46224 | PZ7: 46225 | QA7: 46227 | QB7: 46230 | QC7: 46231 | QD7: 46232 | QE7: 46233 | QF7: 46234 | QG7: 46237 | QH7: 46238 | QI7: 46239 | QJ7: 46240 | QK7: 46241 | QL7: 46244 | QM7: 46245 | QN7: 46246 | QO7: 46247 | QP7: 46248 | QQ7: 46251 | QR7: 46252 | QS7: 46253 | QT7: 46254 | QU7: 46255 | QV7: 46258 | QW7: 46259 | QX7: 46260 | QY7: 46261 | QZ7: 46262 | RA7: 46265
A8: AMAZON | B8: Báscula Digital de Vidrio Antideslizante | G8: 12 | AF8: 12 | AJ8: 6 | AP8: 12 | AQ8: 18 | BK8: 12 | BV8: 18 | CL8: 6 | DI8: 6 | DZ8: 6 | FR8: 6 | FY8: 6 | GA8: 6 | GF8: 18 | GK8: 6 | GM8: 6 | GU8: 6 | HB8: 6 | HQ8: 6 | HZ8: 6 | IS8: 6 | JB8: 6 | KK8: 6 | KY8: 6 | KZ8: 6 | LC8: 6 | LL8: 6 | LQ8: 6 | NY8: 6 | NZ8: 6 | OJ8: 6 | OL8: 6 | OT8: 6 | OU8: 6 | OV8: 12 | OY8: 6 | OZ8: 6 | QL8: 6
A9: AMAZON | B9: Báscula Digital de Vidrio Marmol | F9: 6 | G9: 6 | BV9: 6 | DI9: 6 | DU9: 6 | EI9: 6 | FF9: 6 | FY9: 6 | GK9: 12 | JF9: 6 | KY9: 6 | LC9: 6 | LH9: 6 | LL9: 6 | MH9: 6 | MR9: 6 | OS9: 6 | OX9: 6 | QG9: 6
A10: AMAZON | B10: Báscula Digital de Vidrio Transparente | G10: 12 | CL10: 6 | DU10: 6 | EI10: 6 | GM10: 6 | GU10: 6 | GY10: 6 | JF10: 6 | KY10: 6 | LH10: 6 | LJ10: 6 | MH10: 6 | OS10: 6 | OV10: 6
A11: AMAZON | B11: Cojin Cuadrad Memory Foam | F11: 5 | G11: 1 | PY11: 2 | QG11: 2 | QQ11: 1 | QV11: 1 | QW11: 1 | QY11: 1
A12: AMAZON | B12: Inodoro Portatil con tapa y brazo | D12: 4 | F12: 1 | G12: 1
A13: AMAZON | B13: Kit de Nebulización Adulto | OS13: 100
A14: AMAZON | B14: Kit de Nebulización Pediátrico | OS14: 100 | QW14: 100
A15: AMAZON | B15: Nebulizador Adulto Moderno NBA-10WA | NY15: 6
A16: AMAZON | B16: Nebulizador Adulto Moderno Tapa Azul | E16: 6 | H16: 6 | L16: 24 | BY16: 6 | EI16: 12 | EU16: 6 | FA16: 54 | JK16: 6 | KK16: 6 | KP16: 6 | MX16: 6
A17: AMAZON | B17: Nebulizador Pediatrico Buho Celeste | JB17: 6 | KD17: 6 | KI17: 6 | LQ17: 6
A18: AMAZON | B18: Nebulizador Pediatrico Buho Rosado | JB18: 6 | LC18: 6 | LL18: 6 | LQ18: 6
A19: AMAZON | B19: Nebulizador Pediatrico Elefante Rosa | ED19: 6 | EL19: 6 | EO19: 6 | JK19: 6 | JX19: 6 | MH19: 6
A20: AMAZON | B20: Pack Tarjetas Aromatizantes con Frases Motivacionales | GR20: 30
A21: AMAZON | B21: Pack Tarjetas Aromatizantes con Frases Religiosas | GR21: 30
A22: AMAZON | B22: Pack Tarjetas Aromatizantes con Imagenes Religiosas | GR22: 30
A23: AMAZON | B23: Prueba de Embarazo Wellpro Response Tipo Lápiz | HJ23: 100 | HQ23: 100 | IS23: 100 | JR23: 100 | KY23: 100 | LQ23: 100 | LV23: 100 | LZ23: 100 | NY23: 100 | OL23: 100
A24: AMAZON | B24: Silla de Baño con Respaldo | D24: 4 | F24: 1 | G24: 1 | PS24: 1
A25: AMAZON | B25: Silla de Ruedas STD | D25: 3 | F25: 1 | GF25: 1 | GR25: 1
A26: AMAZON | B26: Tarjeta Aromatizante con Frases Motivacionales | GU26: 240 | LC26: 120 | MX26: 120 | NY26: 120
A27: AMAZON | B27: Tarjeta Aromatizante con Frases Religiosas | IW27: 120 | KB27: 120 | MX27: 120 | OM27: 120
A28: AMAZON | B28: Tarjeta Aromatizante con Imágenes Religiosas | FO28: 720
A29: AMAZON | B29: Termómetro Pediatrico Cute Animals Koala | G29: 240 | I29: 240 | R29: 240 | AF29: 240 | AQ29: 240 | BG29: 240 | BK29: 480 | BV29: 240 | DU29: 240 | EY29: 240 | FX29: 240 | HU29: 240 | IA29: 240 | JE29: 240 | JR29: 240 | LL29: 240 | LU29: 240 | NE29: 240 | NX29: 480 | QL29: 240
A30: AMAZON | B30: Termómetro Pediatrico Cute Animals Osito | G30: 240 | M30: 240 | AC30: 240 | BK30: 480 | CI30: 240 | EV30: 240 | GA30: 240 | HX30: 240 | IS30: 240 | JH30: 240 | KT30: 240 | LL30: 240 | LZ30: 240 | NZ30: 240 | OX30: 240 | QN30: 240
A31: AMAZON | B31: Termómetro Pediatrico Cute Animals Panda | G31: 240 | DU31: 240 | IS31: 240 | LL31: 240 | OJ31: 240 | PZ31: 240 | QL31: 240 | QN31: 240 | QT31: 240
A32: AMAZON | B32: Termómetro Pediatrico Cute Animals Ranita | G32: 240 | FF32: 240 | LC32: 240 | PB32: 240
A33: ANGELICA BENITEZ HERNANDEZ | JB33: 53
A34: AP DISTRIBUCION | HQ34: 21600
A35: CHEDRAUI | IR35: 1
A36: CONAFAR | LO36: 340 | PR36: 242 | RA36: 70
A37: COPPEL | IW37: 61 | KL37: 2 | KM37: 2 | KW37: 9 | LL37: 8
A38: COPPEL MARKETPLACE | HF38: 1 | HH38: 2 | HO38: 2 | HR38: 2 | HY38: 1 | KK38: 1 | LS38: 1 | MX38: 1
A39: DANIEL ZARCO SALINAS | IS39: 12 | KM39: 10
A40: FANASA | B40: Nebulizador Adulto Compacto | MK40: 50 | OA40: 6 | OD40: 11 | OJ40: 10 | OT40: 9 | OW40: 20 | PC40: 10 | PG40: 5 | PL40: 3 | PP40: 39 | QT40: 2
A41: FANASA | B41: Nebulizador Adulto Moderno Tapa Azul | MK41: 50 | NK41: 5 | OA41: 5 | OD41: 10 | OJ41: 9 | OT41: 6 | OW41: 20 | PC41: 8 | PG41: 6 | PL41: 2 | PP41: 35
A42: FANASA | B42: Nebulizador Adulto Walmart | NK42: 5
...

Sheet TblProductos
A3: Suma de Cantidad Vendida | B3: Etiquetas de columna
B4: 2024 | C4: 2025 | D4: 2026
A5: Clientes | D5: ene | E5: feb | F5: mar | G5: abr | H5: may | I5: jun | J5: jul | K5: ago
A6: Báscula Digital de Vidrio Antideslizante | B6: 90 | C6: 209 | D6: 28 | E6: 7 | G6: 12 | H6: 32 | I6: 90 | J6: 57 | K6: 64
A7: Báscula Digital de Vidrio Marmol | B7: 18 | C7: 123 | D7: 24 | E7: 6 | F7: 14 | G7: 13 | H7: 5 | I7: 53 | J7: 31 | K7: 52
A8: Báscula Digital de Vidrio Transparente | B8: 12 | C8: 89 | D8: 20 | E8: 7 | F8: 14 | G8: 11 | H8: 5 | I8: 51 | J8: 70 | K8: 63
A9: Cojin Cuadrad Memory Foam | B9: 8 | C9: 16 | D9: 15 | E9: 2 | H9: 13 | J9: 6 | K9: 7
A10: Inodoro Portatil con tapa y brazo | B10: 9 | C10: 85 | D10: 10 | H10: 1 | J10: 1 | K10: 3
A11: Kit de Nebulización Adulto | I11: 105 | J11: 101 | K11: 5
A12: Kit de Nebulización Pediátrico | I12: 105 | J12: 3 | K12: 203
A13: Nebulizador Adulto Compacto | B13: 340 | C13: 2588 | D13: 594 | E13: 123 | F13: 287 | G13: 40 | H13: 139 | I13: 133 | J13: 269 | K13: 129
A14: Nebulizador Adulto Moderno NBA-10WA | E14: 5 | F14: 13 | G14: 1 | H14: 10 | J14: 5 | K14: 2
A15: Nebulizador Adulto Moderno Tapa Azul | B15: 77 | C15: 467 | D15: 226 | E15: 26 | F15: 188 | G15: 69 | H15: 40 | I15: 78 | J15: 66 | K15: 9
A16: Nebulizador Adulto Walmart | B16: 5184 | C16: 5443 | D16: 499 | E16: 608 | F16: 246 | G16: 257 | H16: 100 | I16: 312 | J16: 162 | K16: 150
A17: Nebulizador Pediatrico Buho Blanco | C17: 444 | D17: 314 | E17: 48 | F17: 24 | G17: 24 | H17: 18 | I17: 63 | J17: 6
A18: Nebulizador Pediatrico Buho Celeste | C18: 32 | D18: 57 | E18: 13 | F18: 2 | G18: 2 | J18: 21 | K18: 1
A19: Nebulizador Pediatrico Buho Rosado | C19: 19 | D19: 16 | E19: 15 | F19: 7 | G19: 2 | K19: 4
A20: Nebulizador Pediatrico Elefante Celeste | B20: 3622 | C20: 4755 | D20: 402 | E20: 456 | F20: 270 | G20: 228 | H20: 300 | I20: 332 | J20: 189 | K20: 76
A21: Nebulizador Pediatrico Elefante Rosa | C21: 227 | D21: 37 | E21: 72 | F21: 66 | G21: 72 | H21: 133 | I21: 26 | J21: 134 | K21: 35
A22: Pack Tarjetas Aromatizantes con Frases Motivacionales | C22: 31 | D22: 2
A23: Pack Tarjetas Aromatizantes con Frases Religiosas | C23: 31
A24: Pack Tarjetas Aromatizantes con Imagenes Religiosas | C24: 30
A25: Prueba de Embarazo Wellpro Response Tipo Lápiz | C25: 463 | D25: 141 | E25: 321 | F25: 22 | G25: 41 | H25: 517 | I25: 493 | J25: 295 | K25: 344
A26: Silla de Baño con Respaldo | B26: 6 | C26: 15 | D26: 1 | F26: 1 | H26: 7 | I26: 1 | J26: 1
A27: Silla de Ruedas STD | B27: 5 | C27: 18 | D27: 15 | E27: 2 | F27: 1 | H27: 13
A28: Tarjeta Aromatizante con Frases Motivacionales | C28: 7638 | D28: 165 | F28: 138 | H28: 120 | I28: 38
A29: Tarjeta Aromatizante con Frases Religiosas | C29: 7536 | D29: 27 | F29: 142 | H29: 120 | I29: 23 | K29: 85
A30: Tarjeta Aromatizante con Imágenes Religiosas | C30: 8259 | D30: 30 | F30: 2 | I30: 25
A31: Termómetro Pediatrico Cute Animals Cerdito | C31: 209 | D31: 89 | E31: 36 | F31: 70 | G31: 45 | H31: 76 | I31: 64 | J31: 111 | K31: 76
A32: Termómetro Pediatrico Cute Animals Koala | B32: 2679 | C32: 3747 | D32: 2375 | E32: 370 | F32: 239 | G32: 1055 | H32: 752 | I32: 329 | J32: 254 | K32: 402
A33: Termómetro Pediatrico Cute Animals Osito | B33: 1233 | C33: 2677 | D33: 2164 | E33: 366 | F33: 283 | G33: 866 | H33: 629 | I33: 602 | J33: 232 | K33: 569
A34: Termómetro Pediatrico Cute Animals Panda | B34: 10574 | C34: 19309 | D34: 1279 | E34: 2178 | F34: 504 | G34: 983 | H34: 767 | I34: 1469 | J34: 1019 | K34: 2657
A35: Termómetro Pediatrico Cute Animals Ranita | B35: 255 | C35: 419 | D35: 320 | E35: 31 | F35: 52 | G35: 42 | H35: 71 | I35: 292 | J35: 83 | K35: 43

Sheet Venta
A1: Indica | B1: Fecha | C1: Producto | D1: Cliente | E1: Precio de Venta | F1: Cantidad Vendida | G1: IVA | H1: Total de Venta sin IVA | I1: Total de Venta con IVA | J1: Año | K1: Mes | L1: Día
B2: 45321 | C2: Inodoro Portatil con tapa y brazo | D2: AMAZON | E2: 1068.94 | F2: 1 | G2: 171.03 | H2: 1068.94 | I2: 1239.97 | J2: =YEAR(Ventas_Wellpro[[#This Row],[Fecha]]) -> 2024 | K2: =TEXT(Ventas_Wellpro[[#This Row],[Fecha]],"MMMM") -> enero | L2: =DAY(Ventas_Wellpro[[#This Row],[Fecha]]) -> 30
B3: 45321 | C3: Inodoro Portatil con tapa y brazo | D3: AMAZON | E3: 1068.94 | F3: 3 | G3: 513.09 | H3: 3206.82 | I3: 3719.91 | J3: =YEAR(Ventas_Wellpro[[#This Row],[Fecha]]) -> 2024 | K3: =TEXT(Ventas_Wellpro[[#This Row],[Fecha]],"MMMM") -> enero | L3: =DAY(Ventas_Wellpro[[#This Row],[Fecha]]) -> 30
B4: 45321 | C4: Silla de Baño con Respaldo | D4: AMAZON | E4: 748.26 | F4: 1 | G4: 119.72 | H4: 748.26 | I4: 867.98 | J4: =YEAR(Ventas_Wellpro[[#This Row],[Fecha]]) -> 2024 | K4: =TEXT(Ventas_Wellpro[[#This Row],[Fecha]],"MMMM") -> enero | L4: =DAY(Ventas_Wellpro[[#This Row],[Fecha]]) -> 30
B5: 45321 | C5: Silla de Baño con Respaldo | D5: AMAZON | E5: 748.26 | F5: 3 | G5: 359.16 | H5: 2244.78 | I5: 2603.94 | J5: =YEAR(Ventas_Wellpro[[#This Row],[Fecha]]) -> 2024 | K5: =TEXT(Ventas_Wellpro[[#This Row],[Fecha]],"MMMM") -> enero | L5: =DAY(Ventas_Wellpro[[#This Row],[Fecha]]) -> 30
B6: 45321 | C6: Silla de Ruedas STD | D6: AMAZON | E6: 2419.7 | F6: 3 | G6: 1161.46 | H6: 7259.1 | I6: 8420.56 | J6: =YEAR(Ventas_Wellpro[[#This Row],[Fecha]]) -> 2024 | K6: =TEXT(Ventas_Wellpro[[#This Row],[Fecha]],"MMMM") -> enero | L6: =DAY(Ventas_Wellpro[[#This Row],[Fecha]]) -> 30
B7: 45324 | C7: Nebulizador Adulto Moderno Tapa Azul | D7: AMAZON | E7: 566.83 | F7: 6 | G7: 544.16 | H7: 3400.98 | I7: 3945.14 | J7: =YEAR(Ventas_Wellpro[[#This Row],[Fecha]]) -> 2024 | K7: =TEXT(Ventas_Wellpro[[#This Row],[Fecha]],"MMMM") -> febrero | L7: =DAY(Ventas_Wellpro[[#This Row],[Fecha]]) -> 2
B8: 45329 | C8: Cojin Cuadrad Memory Foam | D8: AMAZON | E8: 160.34 | F8: 5 | G8: 128.27 | H8: 801.7 | I8: 929.97 | J8: =YEAR(Ventas_Wellpro[[#This Row],[Fecha]]) -> 2024 | K8: =TEXT(Ventas_Wellpro[[#This Row],[Fecha]],"MMMM") -> febrero | L8: =DAY(Ventas_Wellpro[[#This Row],[Fecha]]) -> 7
B9: 45329 | C9: Inodoro Portatil con tapa y brazo | D9: AMAZON | E9: 1068.94 | F9: 1 | G9: 171.03 | H9: 1068.94 | I9: 1239.97 | J9: =YEAR(Ventas_Wellpro[[#This Row],[Fecha]]) -> 2024 | K9: =TEXT(Ventas_Wellpro[[#This Row],[Fecha]],"MMMM") -> febrero | L9: =DAY(Ventas_Wellpro[[#This Row],[Fecha]]) -> 7
B10: 45329 | C10: Silla de Baño con Respaldo | D10: AMAZON | E10: 748.26 | F10: 1 | G10: 119.72 | H10: 748.26 | I10: 867.98 | J10: =YEAR(Ventas_Wellpro[[#This Row],[Fecha]]) -> 2024 | K10: =TEXT(Ventas_Wellpro[[#This Row],[Fecha]],"MMMM") -> febrero | L10: =DAY(Ventas_Wellpro[[#This Row],[Fecha]]) -> 7
B11: 45329 | C11: Silla de Ruedas STD | D11: AMAZON | E11: 2419.7 | F11: 1 | G11: 387.15 | H11: 2419.7 | I11: 2806.85 | J11: =YEAR(Ventas_Wellpro[[#This Row],[Fecha]]) -> 2024 | K11: =TEXT(Ventas_Wellpro[[#This Row],[Fecha]],"MMMM") -> febrero | L11: =DAY(Ventas_Wellpro[[#This Row],[Fecha]]) -> 7
B12: 45329 | C12: Báscula Digital de Vidrio Marmol | D12: AMAZON | E12: 176.38 | F12: 6 | G12: 169.32 | H12: 1058.28 | I12: 1227.6 | J12: =YEAR(Ventas_Wellpro[[#This Row],[Fecha]]) -> 2024 | K12: =TEXT(Ventas_Wellpro[[#This Row],[Fecha]],"MMMM") -> febrero | L12: =DAY(Ventas_Wellpro[[#This Row],[Fecha]]) -> 7
B13: 45335 | C13: Báscula Digital de Vidrio Antideslizante | D13: AMAZON | E13: 176.38 | F13: 6 | G13: 169.32 | H13: 1058.28 | I13: 1227.6 | J13: =YEAR(Ventas_Wellpro[[#This Row],[Fecha]]) -> 2024 | K13: =TEXT(Ventas_Wellpro[[#This Row],[Fecha]],"MMMM") -> febrero | L13: =DAY(Ventas_Wellpro[[#This Row],[Fecha]]) -> 13
... B1812: 45901 | C1812: Termómetro Pediatrico Cute Animals Koala | D1812: AMAZON | E1812: 103.34 | F1812: 240 | G1812: 3968.256 | H1812: 24801.6 | I1812: 28769.856 | J1812: =YEAR(Ventas_Wellpro[[#This Row],[Fecha]]) -> 2025 | K1812: =TEXT(Ventas_Wellpro[[#This Row],[Fecha]],"MMMM") -> septiembre | L1812: =DAY(Ventas_Wellpro[[#This Row],[Fecha]]) -> 1
A1813: Aplicar aquí | B1813: 45901 | C1813: Silla de Ruedas STD | D1813: WALMART MARKETPLACE | E1813: 2585.34 | F1813: 1 | G1813: 413.6544 | H1813: 2585.34 | I1813: 2998.9944 | J1813: =YEAR(Ventas_Wellpro[[#This Row],[Fecha]]) -> 2025 | K1813: =TEXT(Ventas_Wellpro[[#This Row],[Fecha]],"MMMM") -> septiembre | L1813: =DAY(Ventas_Wellpro[[#This Row],[Fecha]]) -> 1
B1814: 45901 | C1814: Inodoro Portatil con tapa y brazo | D1814: MERCADO LIBRE | E1814: 1706.9 | F1814: 1 | G1814: 273.104 | H1814: 1706.9 | I1814: 1980.004 | J1814: =YEAR(Ventas_Wellpro[[#This Row],[Fecha]]) -> 2025 | K1814: =TEXT(Ventas_Wellpro[[#This Row],[Fecha]],"MMMM") -> septiembre | L1814: =DAY(Ventas_Wellpro[[#This Row],[Fecha]]) -> 1
B1815: 45901 | C1815: Cojin Cuadrad Memory Foam | D1815: WALMART MARKETPLACE | E1815: 0 | F1815: 1 | G1815: 0 | H1815: 0 | I1815: 0 | J1815: =YEAR(Ventas_Wellpro[[#This Row],[Fecha]]) -> 2025 | K1815: =TEXT(Ventas_Wellpro[[#This Row],[Fecha]],"MMMM") -> septiembre | L1815: =DAY(Ventas_Wellpro[[#This Row],[Fecha]]) -> 1
B1816: 45901 | C1816: Báscula Digital de Vidrio Marmol | D1816: MERCADO LIBRE | E1816: 343.97 | F1816: 1 | G1816: 55.0352 | H1816: 343.97 | I1816: 399.0052 | J1816: =YEAR(Ventas_Wellpro[[#This Row],[Fecha]]) -> 2025 | K1816: =TEXT(Ventas_Wellpro[[#This Row],[Fecha]],"MMMM") -> septiembre | L1816: =DAY(Ventas_Wellpro[[#This Row],[Fecha]]) -> 1
B1817: 45901 | C1817: Termómetro Pediatrico Cute Animals Osito | D1817: MERCADO LIBRE | E1817: 137.79 | F1817: 1 | G1817: 22.0464 | H1817: 137.79 | I1817: 159.8364 | J1817: =YEAR(Ventas_Wellpro[[#This Row],[Fecha]]) -> 2025 | K1817: =TEXT(Ventas_Wellpro[[#This Row],[Fecha]],"MMMM") -> septiembre | L1817: =DAY(Ventas_Wellpro[[#This Row],[Fecha]]) -> 1
B1818: 45901 | C1818: Termómetro Pediatrico Cute Animals Panda | D1818: MERCADO LIBRE | E1818: 136.55 | F1818: 1 | G1818: 21.848 | H1818: 136.55 | I1818: 158.398 | J1818: =YEAR(Ventas_Wellpro[[#This Row],[Fecha]]) -> 2025 | K1818: =TEXT(Ventas_Wellpro[[#This Row],[Fecha]],"MMMM") -> septiembre | L1818: =DAY(Ventas_Wellpro[[#This Row],[Fecha]]) -> 1
B1819: 45901 | C1819: Báscula Digital de Vidrio Transparente | D1819: MERCADO LIBRE | E1819: 340.86 | F1819: 1 | G1819: 54.5376 | H1819: 340.86 | I1819: 395.3976 | J1819: =YEAR(Ventas_Wellpro[[#This Row],[Fecha]]) -> 2025 | K1819: =TEXT(Ventas_Wellpro[[#This Row],[Fecha]],"MMMM") -> septiembre | L1819: =DAY(Ventas_Wellpro[[#This Row],[Fecha]]) -> 1
B1820: 45901 | C1820: Termómetro Pediatrico Cute Animals Ranita | D1820: MERCADO LIBRE | E1820: 137.79 | F1820: 1 | G1820: 22.0464 | H1820: 137.79 | I1820: 159.8364 | J1820: =YEAR(Ventas_Wellpro[[#This Row],[Fecha]]) -> 2025 | K1820: =TEXT(Ventas_Wellpro[[#This Row],[Fecha]],"MMMM") -> septiembre | L1820: =DAY(Ventas_Wellpro[[#This Row],[Fecha]]) -> 1
B1821: 45902 | C1821: Nebulizador Adulto Moderno Tapa Azul | D1821: MERCADO LIBRE | E1821: 905.16 | F1821: 1 | G1821: 144.8256 | H1821: 905.16 | I1821: 1049.9856 | J1821: =YEAR(Ventas_Wellpro[[#This Row],[Fecha]]) -> 2025 | K1821: =TEXT(Ventas_Wellpro[[#This Row],[Fecha]],"MMMM") -> septiembre | L1821: =DAY(Ventas_Wellpro[[#This Row],[Fecha]]) -> 2
B1822: 45902 | C1822: Nebulizador Adulto Walmart | D1822: WALMART | E1822: 498.66 | F1822: 6 | G1822: 478.7136 | H1822: 2991.96 | I1822: 3470.6736 | J1822: =YEAR(Ventas_Wellpro[[#This Row],[Fecha]]) -> 2025 | K1822: =TEXT(Ventas_Wellpro[[#This Row],[Fecha]],"MMMM") -> septiembre | L1822: =DAY(Ventas_Wellpro[[#This Row],[Fecha]]) -> 2
B1823: 45902 | C1823: Nebulizador Adulto Walmart | D1823: WALMART | E1823: 498.66 | F1823: 6 | G1823: 478.7136 | H1823: 2991.96 | I1823: 3470.6736 | J1823: =YEAR(Ventas_Wellpro[[#This Row],[Fecha]]) -> 2025 | K1823: =TEXT(Ventas_Wellpro[[#This Row],[Fecha]],"MMMM") -> septiembre | L1823: =DAY(Ventas_Wellpro[[#This Row],[Fecha]]) -> 2
B1824: 45902 | C1824: Nebulizador Adulto Walmart | D1824: WALMART | E1824: 498.66 | F1824: 6 | G1824: 478.7136 | H1824: 2991.96 | I1824: 3470.6736 | J1824: =YEAR(Ventas_Wellpro[[#This Row],[Fecha]]) -> 2025 | K1824: =TEXT(Ventas_Wellpro[[#This Row],[Fecha]],"MMMM") -> septiembre | L1824: =DAY(Ventas_Wellpro[[#This Row],[Fecha]]) -> 2
B1825: 45902 | C1825: Termómetro Pediatrico Cute Animals Cerdito | D1825: MERCADO LIBRE | E1825: 137.79 | F1825: 1 | G1825: 22.0464 | H1825: 137.79 | I1825: 159.8364 | J1825: =YEAR(Ventas_Wellpro[[#This Row],[Fecha]]) -> 2025 | K1825: =TEXT(Ventas_Wellpro[[#This Row],[Fecha]],"MMMM") -> septiembre | L1825: =DAY(Ventas_Wellpro[[#This Row],[Fecha]]) -> 2
... B1982: 45930 | C1982: Inodoro Portatil con tapa y brazo | D1982: MERCADO LIBRE | E1982: 1706.9 | F1982: 1 | G1982: 273.104 | H1982: 1706.9 | I1982: 1980.004 | J1982: =YEAR(Ventas_Wellpro[[#This Row],[Fecha]]) -> 2025 | K1982: =TEXT(Ventas_Wellpro[[#This Row],[Fecha]],"MMMM") -> septiembre | L1982: =DAY(Ventas_Wellpro[[#This Row],[Fecha]]) -> 30
B1983: 45931 | C1983: Nebulizador Adulto Walmart | D1983: WALMART | E1983: 498.66 | F1983: 6 | G1983: =+(Ventas_Wellpro[[#This Row],[Precio de Venta]]*0.16)*Ventas_Wellpro[[#This Row],[Cantidad Vendida]] -> 478.7136 | H1983: 2991.96 | I1983: =+Ventas_Wellpro[[#This Row],[Total de Venta sin IVA]]+Ventas_Wellpro[[#This Row],[IVA]] -> 3470.6736 | J1983: =YEAR(Ventas_Wellpro[[#This Row],[Fecha]]) -> 2025 | K1983: =TEXT(Ventas_Wellpro[[#This Row],[Fecha]],"MMMM") -> octubre | L1983: =DAY(Ventas_Wellpro[[#This Row],[Fecha]]) -> 1
B1984: 45931 | C1984: Nebulizador Adulto Walmart | D1984: WALMART | E1984: 498.66 | F1984: 36 | G1984: =+(Ventas_Wellpro[[#This Row],[Precio de Venta]]*0.16)*Ventas_Wellpro[[#This Row],[Cantidad Vendida]] -> 2872.2816 | H1984: 17951.76 | I1984: =+Ventas_Wellpro[[#This Row],[Total de Venta sin IVA]]+Ventas_Wellpro[[#This Row],[IVA]] -> 20824.042 | J1984: =YEAR(Ventas_Wellpro[[#This Row],[Fecha]]) -> 2025 | K1984: =TEXT(Ventas_Wellpro[[#This Row],[Fecha]],"MMMM") -> octubre | L1984: =DAY(Ventas_Wellpro[[#This Row],[Fecha]]) -> 1
B1985: 45931 | C1985: Nebulizador Adulto Walmart | D1985: WALMART | E1985: 498.66 | F1985: 12 | G1985: =+(Ventas_Wellpro[[#This Row],[Precio de Venta]]*0.16)*Ventas_Wellpro[[#This Row],[Cantidad Vendida]] -> 957.4272 | H1985: 5983.92 | I1985: =+Ventas_Wellpro[[#This Row],[Total de Venta sin IVA]]+Ventas_Wellpro[[#This Row],[IVA]] -> 6941.3472 | J1985: =YEAR(Ventas_Wellpro[[#This Row],[Fecha]]) -> 2025 | K1985: =TEXT(Ventas_Wellpro[[#This Row],[Fecha]],"MMMM") -> octubre | L1985: =DAY(Ventas_Wellpro[[#This Row],[Fecha]]) -> 1
