Workbook

Sheet Tbl
A4: COSTO | B4: Fecha | C4: Descripcion | D4: COSTOS | E4: Inventario Inicial | F4: Compra | G4: Entrada dev | H4: Salida | I4: Salida Almacen | J4: Inventario Final
A5: =_xlfn.XLOOKUP(Tabla1[[#This Row],[Descripcion]],Costos!A:A,Costos!B:B) -> 1086.7487 | B5: 46023 | C5: Silla de Ruedas Standar | D5: 1086.7487 | E5: 29 | F5: 0 | G5: 0 | H5: 15 | I5: 0 | J5: =(E5+G5+F5)-(H5+I5) -> 14
A6: =_xlfn.XLOOKUP(Tabla1[[#This Row],[Descripcion]],Costos!A:A,Costos!B:B) -> 349.3127 | B6: 46023 | C6: Silla de Baño con Respaldo | D6: 349.3127 | E6: =519+4 -> 523 | F6: 0 | G6: 0 | H6: 0 | I6: 0 | J6: =(E6+G6+F6)-(H6+I6) -> 523
A7: =_xlfn.XLOOKUP(Tabla1[[#This Row],[Descripcion]],Costos!A:A,Costos!B:B) -> 447.78148 | B7: 46023 | C7: Nebulizador Pediatrico Elefante Rosa | D7: 447.78148 | E7: =11354 -> 11354 | F7: 0 | G7: 0 | H7: 37 | I7: 0 | J7: =(E7+G7+F7)-(H7+I7) -> 11317
A8: =_xlfn.XLOOKUP(Tabla1[[#This Row],[Descripcion]],Costos!A:A,Costos!B:B) -> 451.39646 | B8: 46023 | C8: Nebulizador Pediatrico Elefante Celeste | D8: 451.39646 | E8: 3173 | F8: 0 | G8: 144 | H8: 390 | I8: 0 | J8: =(E8+G8+F8)-(H8+I8) -> 2927
A9: =_xlfn.XLOOKUP(Tabla1[[#This Row],[Descripcion]],Costos!A:A,Costos!B:B) -> 58.319145 | B9: 46023 | C9: Termometro Pediatrico Osito | D9: 58.319145 | E9: =22727+20+464 -> 23211 | F9: 0 | G9: 0 | H9: 2165 | I9: 0 | J9: =(E9+G9+F9)-(H9+I9) -> 21046
A10: =_xlfn.XLOOKUP(Tabla1[[#This Row],[Descripcion]],Costos!A:A,Costos!B:B) -> 58.065092 | B10: 46023 | C10: Termometro Pediatrico Koala | D10: 58.065092 | E10: =23069+20+472 -> 23561 | F10: 0 | G10: 0 | H10: 2136 | I10: 0 | J10: =(E10+G10+F10)-(H10+I10) -> 21425
A11: =_xlfn.XLOOKUP(Tabla1[[#This Row],[Descripcion]],Costos!A:A,Costos!B:B) -> 57.201051 | B11: 46023 | C11: Termometro Pediatrico Panda | D11: 57.201051 | E11: =13584+20 -> 13604 | F11: 0 | G11: 0 | H11: 1279 | I11: 0 | J11: =(E11+G11+F11)-(H11+I11) -> 12325
A12: =_xlfn.XLOOKUP(Tabla1[[#This Row],[Descripcion]],Costos!A:A,Costos!B:B) -> 60.761 | B12: 46023 | C12: Termometro Pediatrico Ranita | D12: 60.761 | E12: =8741+20+462 -> 9223 | F12: 0 | G12: 0 | H12: 320 | I12: 0 | J12: =(E12+G12+F12)-(H12+I12) -> 8903
A13: =_xlfn.XLOOKUP(Tabla1[[#This Row],[Descripcion]],Costos!A:A,Costos!B:B) -> 465.8061 | B13: 46023 | C13: Nebulizador Adulto Moderno NBA-01WA | D13: 465.8061 | E13: =5540+177 -> 5717 | F13: 0 | G13: 0 | H13: 72 | I13: 0 | J13: =(E13+G13+F13)-(H13+I13) -> 5645
A14: =_xlfn.XLOOKUP(Tabla1[[#This Row],[Descripcion]],Costos!A:A,Costos!B:B) -> 517.4982 | B14: 46023 | C14: Inodoro Portatil | D14: 517.4982 | E14: 7 | F14: 0 | G14: 3 | H14: 10 | I14: 0 | J14: =(E14+G14+F14)-(H14+I14) -> 0
A15: =_xlfn.XLOOKUP(Tabla1[[#This Row],[Descripcion]],Costos!A:A,Costos!B:B) -> 154.16365 | B15: 46023 | C15: Bascula Digital de Vidrio Transparente | D15: 154.16365 | E15: 881 | F15: 0 | G15: 0 | H15: 14 | I15: 0 | J15: =(E15+G15+F15)-(H15+I15) -> 867
A16: =_xlfn.XLOOKUP(Tabla1[[#This Row],[Descripcion]],Costos!A:A,Costos!B:B) -> 147.5766 | B16: 46023 | C16: Bascula Digital de Vidrio Marmol | D16: 147.5766 | E16: =720+114 -> 834 | F16: 0 | G16: 0 | H16: 24 | I16: 0 | J16: =(E16+G16+F16)-(H16+I16) -> 810
A17: =_xlfn.XLOOKUP(Tabla1[[#This Row],[Descripcion]],Costos!A:A,Costos!B:B) -> 147.5766 | B17: 46023 | C17: Bascula Digital de Vidrio Antideslizante | D17: 147.5766 | E17: =563+103 -> 666 | F17: 0 | G17: 0 | H17: 34 | I17: 0 | J17: =(E17+G17+F17)-(H17+I17) -> 632
A18: =_xlfn.XLOOKUP(Tabla1[[#This Row],[Descripcion]],Costos!A:A,Costos!B:B) -> 170.34 | B18: 46023 | C18: Cojin de Espuma de Memoria Cuadrado | D18: 170.34 | E18: 1475 | F18: 0 | G18: 0 | H18: 15 | I18: 0 | J18: =(E18+G18+F18)-(H18+I18) -> 1460
A19: =_xlfn.XLOOKUP(Tabla1[[#This Row],[Descripcion]],Costos!A:A,Costos!B:B) -> 434.24951 | B19: 46023 | C19: Nebulizador Adulto NBA-05WA | D19: 434.24951 | E19: 4237 | F19: 0 | G19: 0 | H19: 744 | I19: 0 | J19: =(E19+G19+F19)-(H19+I19) -> 3493
A20: 441.3131 | B20: 46023 | C20: Nebulizador Adulto NBA-00WA | D20: 441.3131 | E20: =6305+88 -> 6393 | F20: 0 | G20: 0 | H20: 480 | I20: 0 | J20: =(E20+G20+F20)-(H20+I20) -> 5913
A21: =_xlfn.XLOOKUP(Tabla1[[#This Row],[Descripcion]],Costos!A:A,Costos!B:B) -> 17.944525 | B21: 46023 | C21: Prueba de Embarazo Wellpro Response Tipo Lápiz | D21: 17.944525 | E21: =199437+20 -> 199457 | F21: 0 | G21: 0 | H21: 141 | I21: 0 | J21: =(E21+G21+F21)-(H21+I21) -> 199316
A22: =_xlfn.XLOOKUP(Tabla1[[#This Row],[Descripcion]],Costos!A:A,Costos!B:B) -> 57.19 | B22: 46023 | C22: Termometro Pediatrico Cerdito | D22: 57.19 | E22: =6999+20+469 -> 7488 | F22: 0 | G22: 0 | H22: 91 | I22: 0 | J22: =(E22+G22+F22)-(H22+I22) -> 7397
A23: =_xlfn.XLOOKUP(Tabla1[[#This Row],[Descripcion]],Costos!A:A,Costos!B:B) -> 417.75261 | B23: 46023 | C23: Nebulizador Adulto Moderno NBA-10WA | D23: 417.75261 | E23: 1477 | F23: 0 | G23: 0 | H23: 6 | I23: 0 | J23: =(E23+G23+F23)-(H23+I23) -> 1471
A24: =_xlfn.XLOOKUP(Tabla1[[#This Row],[Descripcion]],Costos!A:A,Costos!B:B) -> 417.75261 | B24: 46023 | C24: Nebulizador Pediátrico Búho Blanco | D24: 417.75261 | E24: 1981 | F24: 0 | G24: 0 | H24: 314 | I24: 0 | J24: =(E24+G24+F24)-(H24+I24) -> 1667
A25: =_xlfn.XLOOKUP(Tabla1[[#This Row],[Descripcion]],Costos!A:A,Costos!B:B) -> 417.75261 | B25: 46023 | C25: Nebulizador Pediátrico Búho Rosado | D25: 417.75261 | E25: 1481 | F25: 0 | G25: 0 | H25: 17 | I25: 0 | J25: =(E25+G25+F25)-(H25+I25) -> 1464
A26: =_xlfn.XLOOKUP(Tabla1[[#This Row],[Descripcion]],Costos!A:A,Costos!B:B) -> 417.75261 | B26: 46023 | C26: Nebulizador Pediátrico Búho Celeste | D26: 417.75261 | E26: 1465 | F26: 0 | G26: 0 | H26: 3 | I26: 0 | J26: =(E26+G26+F26)-(H26+I26) -> 1462
A27: =_xlfn.XLOOKUP(Tabla1[[#This Row],[Descripcion]],Costos!A:A,Costos!B:B) -> 7.69 | B27: 46023 | C27: Tarjetas Aromatizantes con Imagenes Religiosas | D27: 7.69 | E27: 61944 | F27: 0 | G27: 0 | H27: 0 | I27: 0 | J27: =(E27+G27+F27)-(H27+I27) -> 61944
A28: =_xlfn.XLOOKUP(Tabla1[[#This Row],[Descripcion]],Costos!A:A,Costos!B:B) -> 7.69 | B28: 46023 | C28: Tarjetas Aromatizantes con Frases Motivacionales | D28: 7.69 | E28: 104467 | F28: 0 | G28: 0 | H28: 120 | I28: 0 | J28: =(E28+G28+F28)-(H28+I28) -> 104347
A29: =_xlfn.XLOOKUP(Tabla1[[#This Row],[Descripcion]],Costos!A:A,Costos!B:B) -> 7.69 | B29: 46023 | C29: Tarjetas Aromatizantes con Frases Religiosas | D29: 7.69 | E29: 98208 | F29: 0 | G29: 0 | H29: 0 | I29: 0 | J29: =(E29+G29+F29)-(H29+I29) -> 98208
A30: =_xlfn.XLOOKUP(Tabla1[[#This Row],[Descripcion]],Costos!A:A,Costos!B:B) -> 184.56 | B30: 46023 | C30: Pack Tarjetas Aromatizantes Mix Religioso | D30: 184.56 | E30: 2072 | F30: 0 | G30: 0 | H30: 0 | I30: 0 | J30: =(E30+G30+F30)-(H30+I30) -> 2072
A31: =_xlfn.XLOOKUP(Tabla1[[#This Row],[Descripcion]],Costos!A:A,Costos!B:B) -> 1086.7487 | B31: 46054 | C31: Silla de Ruedas Standar | D31: 1086.7487 | E31: 14 | F31: 0 | G31: 0 | H31: 2 | I31: 0 | J31: =(E31+G31+F31)-(H31+I31) -> 12
A32: =_xlfn.XLOOKUP(Tabla1[[#This Row],[Descripcion]],Costos!A:A,Costos!B:B) -> 349.3127 | B32: 46054 | C32: Silla de Baño con Respaldo | D32: 349.3127 | E32: 523 | F32: 0 | G32: 0 | H32: 0 | I32: 0 | J32: =(E32+G32+F32)-(H32+I32) -> 523
A33: =_xlfn.XLOOKUP(Tabla1[[#This Row],[Descripcion]],Costos!A:A,Costos!B:B) -> 447.78148 | B33: 46054 | C33: Nebulizador Pediatrico Elefante Rosa | D33: 447.78148 | E33: 11317 | F33: 0 | G33: 0 | H33: 76 | I33: 0 | J33: =(E33+G33+F33)-(H33+I33) -> 11241
A34: =_xlfn.XLOOKUP(Tabla1[[#This Row],[Descripcion]],Costos!A:A,Costos!B:B) -> 451.39646 | B34: 46054 | C34: Nebulizador Pediatrico Elefante Celeste | D34: 451.39646 | E34: 2927 | F34: 0 | G34: 0 | H34: 460 | I34: 0 | J34: =(E34+G34+F34)-(H34+I34) -> 2467
... A136: =_xlfn.XLOOKUP(Tabla1[[#This Row],[Descripcion]],Costos!A:A,Costos!B:B) -> 36.413524 | B136: 46143 | C136: Kit de Nebulización Pediátrico | D136: 36.413524 | E136: 10000 | F136: 0 | G136: 0 | H136: 0 | I136: 107 | J136: =(E136+G136+F136)-(H136+I136) -> 9893
A137: =_xlfn.XLOOKUP(Tabla1[[#This Row],[Descripcion]],Costos!A:A,Costos!B:B) -> 1086.7487 | B137: 46174 | C137: Silla de Ruedas Standar | D137: 1086.7487 | E137: 0 | J137: =(E137+G137+F137)-(H137+I137) -> 0
A138: =_xlfn.XLOOKUP(Tabla1[[#This Row],[Descripcion]],Costos!A:A,Costos!B:B) -> 349.3127 | B138: 46174 | C138: Silla de Baño con Respaldo | D138: 349.3127 | E138: 513 | G138: 1 | H138: 1 | J138: =(E138+G138+F138)-(H138+I138) -> 513
A139: =_xlfn.XLOOKUP(Tabla1[[#This Row],[Descripcion]],Costos!A:A,Costos!B:B) -> 447.78148 | B139: 46174 | C139: Nebulizador Pediatrico Elefante Rosa | D139: 447.78148 | E139: 4934 | G139: 6000 | H139: 6008 | I139: 1 | J139: =(E139+G139+F139)-(H139+I139) -> 4925
A140: =_xlfn.XLOOKUP(Tabla1[[#This Row],[Descripcion]],Costos!A:A,Costos!B:B) -> 451.39646 | B140: 46174 | C140: Nebulizador Pediatrico Elefante Celeste | D140: 451.39646 | E140: 9395 | G140: 1 | H140: 584 | I140: 1 | J140: =(E140+G140+F140)-(H140+I140) -> 8811
A141: =_xlfn.XLOOKUP(Tabla1[[#This Row],[Descripcion]],Costos!A:A,Costos!B:B) -> 58.319145 | B141: 46174 | C141: Termometro Pediatrico Osito | D141: 58.319145 | E141: 18561 | G141: 2 | H141: 468 | I141: 25 | J141: =(E141+G141+F141)-(H141+I141) -> 18070
A142: =_xlfn.XLOOKUP(Tabla1[[#This Row],[Descripcion]],Costos!A:A,Costos!B:B) -> 58.065092 | B142: 46174 | C142: Termometro Pediatrico Koala | D142: 58.065092 | E142: 18625 | H142: 309 | I142: 5 | J142: =(E142+G142+F142)-(H142+I142) -> 18311
A143: =_xlfn.XLOOKUP(Tabla1[[#This Row],[Descripcion]],Costos!A:A,Costos!B:B) -> 57.201051 | B143: 46174 | C143: Termometro Pediatrico Panda | D143: 57.201051 | E143: 8034 | H143: 1469 | I143: 5 | J143: =(E143+G143+F143)-(H143+I143) -> 6560
A144: =_xlfn.XLOOKUP(Tabla1[[#This Row],[Descripcion]],Costos!A:A,Costos!B:B) -> 60.761 | B144: 46174 | C144: Termometro Pediatrico Ranita | D144: 60.761 | E144: 8563 | H144: 292 | I144: 5 | J144: =(E144+G144+F144)-(H144+I144) -> 8266
...

Sheet Costos
A1: PRODUCTO | B1: COSTO
A2: Silla de Ruedas Standar | B2: 1086.7487
A3: Silla de Baño con Respaldo | B3: 349.3127
A4: Nebulizador Pediatrico Elefante Rosa | B4: 447.78148
A5: Nebulizador Pediatrico Elefante Celeste | B5: 451.39646
A6: Termometro Pediatrico Osito | B6: 58.319145
A7: Termometro Pediatrico Koala | B7: 58.065092
A8: Termometro Pediatrico Panda | B8: 57.201051
A9: Termometro Pediatrico Ranita | B9: 60.761
A10: Nebulizador Adulto Moderno NBA-01WA | B10: 465.8061
A11: Inodoro Portatil | B11: 517.4982
A12: Bascula Digital de Vidrio Transparente | B12: 154.16365
A13: Bascula Digital de Vidrio Marmol | B13: 147.5766
... A33: Nebulizador Adulto NBA-00WA | B33: 441.3131

Sheet Hoja2
A3: Fecha | B3: Descripcion | C3: COSTOS | D3: Inventario Inicial | E3: Compra | F3: Entrada dev | G3: ALMACEN CONSIGNA SANA | H3: UNEFARM | I3: PROMOCIONALES -TRASPASO | J3: Salida | K3: Salida Almacen | L3: Cancelación Inventario | M3: Inventario Final
A4: 45658 | B4: Silla de Ruedas Standar | E4: 347 | M4: =SUM(D4:H4)-SUM(J4:L4) -> 347
A5: 45658 | B5: Silla de Baño con Respaldo | E5: 844 | M5: =SUM(D5:H5)-SUM(J5:L5) -> 844
A6: 45658 | B6: Nebulizador Pediatrico Elefante Rosa | E6: 3844 | M6: =SUM(D6:H6)-SUM(J6:L6) -> 3844
A7: 45658 | B7: Nebulizador Pediatrico Elefante Celeste | E7: 32 | M7: =SUM(D7:H7)-SUM(J7:L7) -> 32
A8: 45658 | B8: Termometro Pediatrico Osito | E8: 8483 | M8: =SUM(D8:H8)-SUM(J8:L8) -> 8483
A9: 45658 | B9: Termometro Pediatrico Koala | E9: 7278 | M9: =SUM(D9:H9)-SUM(J9:L9) -> 7278
A10: 45658 | B10: Termometro Pediatrico Panda | E10: 105 | M10: =SUM(D10:H10)-SUM(J10:L10) -> 105
A11: 45658 | B11: Termometro Pediatrico Ranita | E11: 9706 | M11: =SUM(D11:H11)-SUM(J11:L11) -> 9706
A12: 45658 | B12: Nebulizador Adulto Moderno NBA-01WA | E12: 6102 | M12: =SUM(D12:H12)-SUM(J12:L12) -> 6102
A13: 45658 | B13: Inodoro Portatil | E13: 440 | M13: =SUM(D13:H13)-SUM(J13:L13) -> 440
A14: 45658 | B14: Bascula Digital de Vidrio Transparente | E14: 973 | M14: =SUM(D14:H14)-SUM(J14:L14) -> 973
A15: 45658 | B15: Bascula Digital de Vidrio Marmol | E15: 973 | M15: =SUM(D15:H15)-SUM(J15:L15) -> 973
... A20: 45658 | B20: Ganchos de Plastico | E20: 81488 | M20: =SUM(D20:H20)-SUM(J20:L20) -> 81488
A21: 45689 | B21: Silla de Ruedas Standar | D21: =M4 -> 347 | M21: =SUM(D21:H21)-SUM(J21:L21) -> 347
A22: 45689 | B22: Silla de Baño con Respaldo | D22: =M5 -> 844 | M22: =SUM(D22:H22)-SUM(J22:L22) -> 844
A23: 45689 | B23: Nebulizador Pediatrico Elefante Rosa | D23: =M6 -> 3844 | M23: =SUM(D23:H23)-SUM(J23:L23) -> 3844
A24: 45689 | B24: Nebulizador Pediatrico Elefante Celeste | D24: =M7 -> 32 | M24: =SUM(D24:H24)-SUM(J24:L24) -> 32
A25: 45689 | B25: Termometro Pediatrico Osito | D25: =M8 -> 8483 | M25: =SUM(D25:H25)-SUM(J25:L25) -> 8483
A26: 45689 | B26: Termometro Pediatrico Koala | D26: =M9 -> 7278 | M26: =SUM(D26:H26)-SUM(J26:L26) -> 7278
A27: 45689 | B27: Termometro Pediatrico Panda | D27: =M10 -> 105 | M27: =SUM(D27:H27)-SUM(J27:L27) -> 105
A28: 45689 | B28: Termometro Pediatrico Ranita | D28: =M11 -> 9706 | M28: =SUM(D28:H28)-SUM(J28:L28) -> 9706
A29: 45689 | B29: Nebulizador Adulto Moderno NBA-01WA | D29: =M12 -> 6102 | M29: =SUM(D29:H29)-SUM(J29:L29) -> 6102
A30: 45689 | B30: Inodoro Portatil | D30: =M13 -> 440 | M30: =SUM(D30:H30)-SUM(J30:L30) -> 440
A31: 45689 | B31: Bascula Digital de Vidrio Transparente | D31: =M14 -> 973 | M31: =SUM(D31:H31)-SUM(J31:L31) -> 973
A32: 45689 | B32: Bascula Digital de Vidrio Marmol | D32: =M15 -> 973 | M32: =SUM(D32:H32)-SUM(J32:L32) -> 973
... A37: 45689 | B37: Ganchos de Plastico | D37: =M20 -> 81488 | M37: =SUM(D37:H37)-SUM(J37:L37) -> 81488
A38: 45717 | B38: Silla de Ruedas Standar | D38: =M21 -> 347 | E38: 45 | M38: =SUM(D38:H38)-SUM(J38:L38) -> 392
A39: 45717 | B39: Silla de Baño con Respaldo | D39: =M22 -> 844 | E39: 535 | M39: =SUM(D39:H39)-SUM(J39:L39) -> 1379
A40: 45717 | B40: Nebulizador Pediatrico Elefante Rosa | D40: =M23 -> 3844 | E40: 11443 | G40: 150 | M40: =SUM(D40:H40)-SUM(J40:L40) -> 15437
A41: 45717 | B41: Nebulizador Pediatrico Elefante Celeste | D41: =M24 -> 32 | E41: 6303 | G41: 150 | M41: =SUM(D41:H41)-SUM(J41:L41) -> 6485
A42: 45717 | B42: Termometro Pediatrico Osito | D42: =M25 -> 8483 | E42: 25095 | G42: 520 | M42: =SUM(D42:H42)-SUM(J42:L42) -> 34098
A43: 45717 | B43: Termometro Pediatrico Koala | D43: =M26 -> 7278 | E43: 26492 | G43: 520 | M43: =SUM(D43:H43)-SUM(J43:L43) -> 34290
A44: 45717 | B44: Termometro Pediatrico Panda | D44: =M27 -> 105 | E44: 30053 | M44: =SUM(D44:H44)-SUM(J44:L44) -> 30158
A45: 45717 | B45: Termometro Pediatrico Ranita | D45: =M28 -> 9706 | E45: 9170 | G45: 520 | M45: =SUM(D45:H45)-SUM(J45:L45) -> 19396
A46: 45717 | B46: Nebulizador Adulto Moderno NBA-01WA | D46: =M29 -> 6102 | E46: 5867 | G46: 198 | M46: =SUM(D46:H46)-SUM(J46:L46) -> 12167
A47: 45717 | B47: Inodoro Portatil | D47: =M30 -> 440 | E47: 77 | M47: =SUM(D47:H47)-SUM(J47:L47) -> 517
A48: 45717 | B48: Bascula Digital de Vidrio Transparente | D48: =M31 -> 973 | E48: 827 | G48: 132 | M48: =SUM(D48:H48)-SUM(J48:L48) -> 1932
A49: 45717 | B49: Bascula Digital de Vidrio Marmol | D49: =M32 -> 973 | E49: 820 | G49: 132 | M49: =SUM(D49:H49)-SUM(J49:L49) -> 1925
A50: 45717 | B50: Bascula Digital de Vidrio Antideslizante | D50: =M33 -> 885 | E50: 738 | G50: 132 | M50: =SUM(D50:H50)-SUM(J50:L50) -> 1755
...
